Workbook

Sheet MARVEL
A1: TAG | B1: State | C1: v | D1: J | E1: e/f | F1: F1/F2 | G1: Ener | H1: unc | I1: NCD | J1: E-ZPE | K1: J | L1: par | M1: nn | N1: E | O1: State | P1: v | Q1: Lambda | R1: Sigma | S1: Omega | T1: W
A2: =B2&"-"&D2&"-"&E2&"-"&C2&"-"&F2 -> X2Pi-0.5-e-0-1 | B2: X2Pi | C2: 0 | D2: 0.5 | E2: e | F2: 1 | G2: 14.275727 | H2: 0.005 | I2: 23 | J2: =G2-G$2 -> 0 | K2: =D2 -> 0.5 | L2: =IF(E2="e",(-1)^(D2-0.5),(-1)^(D2+0.5)) -> 1 | M2: =C2+1+VLOOKUP(B2,states!A$2:C$10,3,FALSE) -> 1 | N2: =J2 -> 0 | O2: =VLOOKUP(B2,states!A$2:C$10,2,FALSE) -> X | P2: =C2 -> 0 | Q2: =VLOOKUP(B2,states!A$2:D$10,4,FALSE) -> 1 | R2: 0.5 | S2: =IF(Q2=0,R2,IF(F2=1,0.5,1.5)) -> 0.5 | T2: =0.01*I2/H2/D2^(1/5)*IF(P2=0,100,1) -> 5284.0124
A3: =B3&"-"&D3&"-"&E3&"-"&C3&"-"&F3 -> X2Pi-e-0.5-e-1-2 | B3: X2Pi-e | C3: 1 | D3: 0.5 | E3: e | F3: 2 | G3: 2746.0771 | H3: 0.00509902 | I3: 7 | J3: =G3-G$2 -> 2731.8014 | K3: =D3 -> 0.5 | L3: =IF(E3="e",(-1)^(D3-0.5),(-1)^(D3+0.5)) -> 1 | M3: =C3+1+VLOOKUP(B3,states!A$2:C$10,3,FALSE) -> 10002 | N3: =J3 -> 2731.8014 | O3: =VLOOKUP(B3,states!A$2:C$10,2,FALSE) -> R | P3: =C3 -> 1 | Q3: =VLOOKUP(B3,states!A$2:D$10,4,FALSE) -> 1 | R3: 0.5 | S3: =IF(Q3=0,R3,IF(F3=1,0.5,1.5)) -> 1.5 | T3: =0.01*I3/H3/D3^(1/5)*IF(P3=0,100,1) -> 15.769478
A4: =B4&"-"&D4&"-"&E4&"-"&C4&"-"&F4 -> X2Pi-0.5-e-1-1 | B4: X2Pi | C4: 1 | D4: 0.5 | E4: e | F4: 1 | G4: 2746.0989 | H4: 0.011946652 | I4: 6 | J4: =G4-G$2 -> 2731.8232 | K4: =D4 -> 0.5 | L4: =IF(E4="e",(-1)^(D4-0.5),(-1)^(D4+0.5)) -> 1 | M4: =C4+1+VLOOKUP(B4,states!A$2:C$10,3,FALSE) -> 2 | N4: =J4 -> 2731.8232 | O4: =VLOOKUP(B4,states!A$2:C$10,2,FALSE) -> X | P4: =C4 -> 1 | Q4: =VLOOKUP(B4,states!A$2:D$10,4,FALSE) -> 1 | R4: 0.5 | S4: =IF(Q4=0,R4,IF(F4=1,0.5,1.5)) -> 0.5 | T4: =0.01*I4/H4/D4^(1/5)*IF(P4=0,100,1) -> 5.7691394
A5: =B5&"-"&D5&"-"&E5&"-"&C5&"-"&F5 -> X2Pi-e-0.5-e-2-2 | B5: X2Pi-e | C5: 2 | D5: 0.5 | E5: e | F5: 2 | G5: 5351.8666 | H5: 0.007141428 | I5: 3 | J5: =G5-G$2 -> 5337.5909 | K5: =D5 -> 0.5 | L5: =IF(E5="e",(-1)^(D5-0.5),(-1)^(D5+0.5)) -> 1 | M5: =C5+1+VLOOKUP(B5,states!A$2:C$10,3,FALSE) -> 10003 | N5: =J5 -> 5337.5909 | O5: =VLOOKUP(B5,states!A$2:C$10,2,FALSE) -> R | P5: =C5 -> 2 | Q5: =VLOOKUP(B5,states!A$2:D$10,4,FALSE) -> 1 | R5: 0.5 | S5: =IF(Q5=0,R5,IF(F5=1,0.5,1.5)) -> 1.5 | T5: =0.01*I5/H5/D5^(1/5)*IF(P5=0,100,1) -> 4.8254986
A6: =B6&"-"&D6&"-"&E6&"-"&C6&"-"&F6 -> X2Pi-0.5-e-2-1 | B6: X2Pi | C6: 2 | D6: 0.5 | E6: e | F6: 1 | G6: 5351.8733 | H6: 0.007141428 | I6: 5 | J6: =G6-G$2 -> 5337.5976 | K6: =D6 -> 0.5 | L6: =IF(E6="e",(-1)^(D6-0.5),(-1)^(D6+0.5)) -> 1 | M6: =C6+1+VLOOKUP(B6,states!A$2:C$10,3,FALSE) -> 3 | N6: =J6 -> 5337.5976 | O6: =VLOOKUP(B6,states!A$2:C$10,2,FALSE) -> X | P6: =C6 -> 2 | Q6: =VLOOKUP(B6,states!A$2:D$10,4,FALSE) -> 1 | R6: 0.5 | S6: =IF(Q6=0,R6,IF(F6=1,0.5,1.5)) -> 0.5 | T6: =0.01*I6/H6/D6^(1/5)*IF(P6=0,100,1) -> 8.0424976
A7: =B7&"-"&D7&"-"&E7&"-"&C7&"-"&F7 -> X2Pi-0.5-e-3-1 | B7: X2Pi | C7: 3 | D7: 0.5 | E7: e | F7: 1 | G7: 7833.0461 | H7: 0.014656497 | I7: 1 | J7: =G7-G$2 -> 7818.7704 | K7: =D7 -> 0.5 | L7: =IF(E7="e",(-1)^(D7-0.5),(-1)^(D7+0.5)) -> 1 | M7: =C7+1+VLOOKUP(B7,states!A$2:C$10,3,FALSE) -> 4 | N7: =J7 -> 7818.7704 | O7: =VLOOKUP(B7,states!A$2:C$10,2,FALSE) -> X | P7: =C7 -> 3 | Q7: =VLOOKUP(B7,states!A$2:D$10,4,FALSE) -> 1 | R7: 0.5 | S7: =IF(Q7=0,R7,IF(F7=1,0.5,1.5)) -> 0.5 | T7: =0.01*I7/H7/D7^(1/5)*IF(P7=0,100,1) -> 0.78374686
A8: =B8&"-"&D8&"-"&E8&"-"&C8&"-"&F8 -> X2Pi-0.5-e-4-1 | B8: X2Pi | C8: 4 | D8: 0.5 | E8: e | F8: 1 | G8: 10190.708 | H8: 0.011203543 | I8: 1 | J8: =G8-G$2 -> 10176.432 | K8: =D8 -> 0.5 | L8: =IF(E8="e",(-1)^(D8-0.5),(-1)^(D8+0.5)) -> 1 | M8: =C8+1+VLOOKUP(B8,states!A$2:C$10,3,FALSE) -> 5 | N8: =J8 -> 10176.432 | O8: =VLOOKUP(B8,states!A$2:C$10,2,FALSE) -> X | P8: =C8 -> 4 | Q8: =VLOOKUP(B8,states!A$2:D$10,4,FALSE) -> 1 | R8: 0.5 | S8: =IF(Q8=0,R8,IF(F8=1,0.5,1.5)) -> 0.5 | T8: =0.01*I8/H8/D8^(1/5)*IF(P8=0,100,1) -> 1.0252992
A9: =B9&"-"&D9&"-"&E9&"-"&C9&"-"&F9 -> B2Sigma-0.5-e-0-2 | B9: B2Sigma | C9: 0 | D9: 0.5 | E9: e | F9: 2 | G9: 25737.799 | H9: 0.0086292 | I9: 10 | J9: =G9-G$2 -> 25723.523 | K9: =D9 -> 0.5 | L9: =IF(E9="e",(-1)^(D9-0.5),(-1)^(D9+0.5)) -> 1 | M9: =C9+1+VLOOKUP(B9,states!A$2:C$10,3,FALSE) -> 51 | N9: =J9 -> 25723.523 | O9: =VLOOKUP(B9,states!A$2:C$10,2,FALSE) -> B | P9: =C9 -> 0 | Q9: =VLOOKUP(B9,states!A$2:D$10,4,FALSE) -> 0 | R9: 0.5 | S9: =IF(Q9=0,R9,IF(F9=1,0.5,1.5)) -> 0.5 | T9: =0.01*I9/H9/D9^(1/5)*IF(P9=0,100,1) -> 1331.176
A10: =B10&"-"&D10&"-"&E10&"-"&C10&"-"&F10 -> B2Sigma-0.5-e-1-2 | B10: B2Sigma | C10: 1 | D10: 0.5 | E10: e | F10: 2 | G10: 27529.844 | H10: 0.008660254 | I10: 11 | J10: =G10-G$2 -> 27515.568 | K10: =D10 -> 0.5 | L10: =IF(E10="e",(-1)^(D10-0.5),(-1)^(D10+0.5)) -> 1 | M10: =C10+1+VLOOKUP(B10,states!A$2:C$10,3,FALSE) -> 52 | N10: =J10 -> 27515.568 | O10: =VLOOKUP(B10,states!A$2:C$10,2,FALSE) -> B | P10: =C10 -> 1 | Q10: =VLOOKUP(B10,states!A$2:D$10,4,FALSE) -> 0 | R10: 0.5 | S10: =IF(Q10=0,R10,IF(F10=1,0.5,1.5)) -> 0.5 | T10: =0.01*I10/H10/D10^(1/5)*IF(P10=0,100,1) -> 14.590429
A11: =B11&"-"&D11&"-"&E11&"-"&C11&"-"&F11 -> C2Sigma-0.5-e-0-1 | B11: C2Sigma | C11: 0 | D11: 0.5 | E11: e | F11: 1 | G11: 31791.656 | H11: 0.006403124 | I11: 4 | J11: =G11-G$2 -> 31777.38 | K11: =D11 -> 0.5 | L11: =IF(E11="e",(-1)^(D11-0.5),(-1)^(D11+0.5)) -> 1 | M11: =C11+1+VLOOKUP(B11,states!A$2:C$10,3,FALSE) -> 101 | N11: =J11 -> 31777.38 | O11: =VLOOKUP(B11,states!A$2:C$10,2,FALSE) -> C | P11: =C11 -> 0 | Q11: =VLOOKUP(B11,states!A$2:D$10,4,FALSE) -> 0 | R11: 0.5 | S11: =IF(Q11=0,R11,IF(F11=1,0.5,1.5)) -> 0.5 | T11: =0.01*I11/H11/D11^(1/5)*IF(P11=0,100,1) -> 717.5862
A12: =B12&"-"&D12&"-"&E12&"-"&C12&"-"&F12 -> C2Sigma-0.5-e-1-1 | B12: C2Sigma | C12: 1 | D12: 0.5 | E12: e | F12: 1 | G12: 34403.214 | H12: 0.050259327 | I12: 2 | J12: =G12-G$2 -> 34388.939 | K12: =D12 -> 0.5 | L12: =IF(E12="e",(-1)^(D12-0.5),(-1)^(D12+0.5)) -> 1 | M12: =C12+1+VLOOKUP(B12,states!A$2:C$10,3,FALSE) -> 102 | N12: =J12 -> 34388.939 | O12: =VLOOKUP(B12,states!A$2:C$10,2,FALSE) -> C | P12: =C12 -> 1 | Q12: =VLOOKUP(B12,states!A$2:D$10,4,FALSE) -> 0 | R12: 0.5 | S12: =IF(Q12=0,R12,IF(F12=1,0.5,1.5)) -> 0.5 | T12: =0.01*I12/H12/D12^(1/5)*IF(P12=0,100,1) -> 0.45710853
A13: =B13&"-"&D13&"-"&E13&"-"&C13&"-"&F13 -> C2Sigma-0.5-e-2-1 | B13: C2Sigma | C13: 2 | D13: 0.5 | E13: e | F13: 1 | G13: 36772.926 | H13: 0.12909768 | I13: 3 | J13: =G13-G$2 -> 36758.65 | K13: =D13 -> 0.5 | L13: =IF(E13="e",(-1)^(D13-0.5),(-1)^(D13+0.5)) -> 1 | M13: =C13+1+VLOOKUP(B13,states!A$2:C$10,3,FALSE) -> 103 | N13: =J13 -> 36758.65 | O13: =VLOOKUP(B13,states!A$2:C$10,2,FALSE) -> C | P13: =C13 -> 2 | Q13: =VLOOKUP(B13,states!A$2:D$10,4,FALSE) -> 0 | R13: 0.5 | S13: =IF(Q13=0,R13,IF(F13=1,0.5,1.5)) -> 0.5 | T13: =0.01*I13/H13/D13^(1/5)*IF(P13=0,100,1) -> 0.26693703
... A1508: =B1508&"-"&D1508&"-"&E1508&"-"&C1508&"-"&F1508 -> A2Delta-34.5-f-0-2 | B1508: A2Delta | C1508: 0 | D1508: 34.5 | E1508: f | F1508: 2 | G1508: 39187.874 | H1508: 0.050249378 | I1508: 1 | J1508: =G1508-G$2 -> 39173.598 | K1508: =D1508 -> 34.5 | L1508: =IF(E1508="e",(-1)^(D1508-0.5),(-1)^(D1508+0.5)) -> -1 | M1508: =C1508+1+VLOOKUP(B1508,states!A$2:C$10,3,FALSE) -> 251 | N1508: =J1508 -> 39173.598 | O1508: =VLOOKUP(B1508,states!A$2:C$10,2,FALSE) -> A | P1508: =C1508 -> 0 | Q1508: =VLOOKUP(B1508,states!A$2:D$10,4,FALSE) -> 2 | R1508: 0.5 | S1508: =IF(Q1508=0,R1508,IF(F1508=1,0.5,1.5)) -> 1.5 | T1508: =0.01*I1508/H1508/D1508^(1/5)*IF(P1508=0,100,1) -> 9.8017922
A1509: =B1509&"-"&D1509&"-"&E1509&"-"&C1509&"-"&F1509 -> X2Pi-35.5-e-0-1 | B1509: X2Pi | C1509: 0 | D1509: 35.5 | E1509: e | F1509: 1 | G1509: 16545.957 | H1509: 0.50251866 | I1509: 2 | J1509: =G1509-G$2 -> 16531.681 | K1509: =D1509 -> 35.5 | L1509: =IF(E1509="e",(-1)^(D1509-0.5),(-1)^(D1509+0.5)) -> -1 | M1509: =C1509+1+VLOOKUP(B1509,states!A$2:C$10,3,FALSE) -> 1 | N1509: =J1509 -> 16531.681 | O1509: =VLOOKUP(B1509,states!A$2:C$10,2,FALSE) -> X | P1509: =C1509 -> 0 | Q1509: =VLOOKUP(B1509,states!A$2:D$10,4,FALSE) -> 1 | R1509: 0.5 | S1509: =IF(Q1509=0,R1509,IF(F1509=1,0.5,1.5)) -> 0.5 | T1509: =0.01*I1509/H1509/D1509^(1/5)*IF(P1509=0,100,1) -> 1.9490911 | U1509: From bernath
A1510: =B1510&"-"&D1510&"-"&E1510&"-"&C1510&"-"&F1510 -> X2Pi-35.5-f-0-1 | B1510: X2Pi | C1510: 0 | D1510: 35.5 | E1510: f | F1510: 1 | G1510: 15749.893 | H1510: 0.50251866 | I1510: 2 | J1510: =G1510-G$2 -> 15735.617 | K1510: =D1510 -> 35.5 | L1510: =IF(E1510="e",(-1)^(D1510-0.5),(-1)^(D1510+0.5)) -> 1 | M1510: =C1510+1+VLOOKUP(B1510,states!A$2:C$10,3,FALSE) -> 1 | N1510: =J1510 -> 15735.617 | O1510: =VLOOKUP(B1510,states!A$2:C$10,2,FALSE) -> X | P1510: =C1510 -> 0 | Q1510: =VLOOKUP(B1510,states!A$2:D$10,4,FALSE) -> 1 | R1510: 0.5 | S1510: =IF(Q1510=0,R1510,IF(F1510=1,0.5,1.5)) -> 0.5 | T1510: =0.01*I1510/H1510/D1510^(1/5)*IF(P1510=0,100,1) -> 1.9490911
A1511: =B1511&"-"&D1511&"-"&E1511&"-"&C1511&"-"&F1511 -> X2Pi-35.5-f-1-1 | B1511: X2Pi | C1511: 1 | D1511: 35.5 | E1511: f | F1511: 1 | G1511: 17844.078 | H1511: 0.007071068 | I1511: 2 | J1511: =G1511-G$2 -> 17829.802 | K1511: =D1511 -> 35.5 | L1511: =IF(E1511="e",(-1)^(D1511-0.5),(-1)^(D1511+0.5)) -> 1 | M1511: =C1511+1+VLOOKUP(B1511,states!A$2:C$10,3,FALSE) -> 2 | N1511: =J1511 -> 17829.802 | O1511: =VLOOKUP(B1511,states!A$2:C$10,2,FALSE) -> X | P1511: =C1511 -> 1 | Q1511: =VLOOKUP(B1511,states!A$2:D$10,4,FALSE) -> 1 | R1511: 0.5 | S1511: =IF(Q1511=0,R1511,IF(F1511=1,0.5,1.5)) -> 0.5 | T1511: =0.01*I1511/H1511/D1511^(1/5)*IF(P1511=0,100,1) -> 1.385158
A1512: =B1512&"-"&D1512&"-"&E1512&"-"&C1512&"-"&F1512 -> X2Pi-35.5-f-1-2 | B1512: X2Pi | C1512: 1 | D1512: 35.5 | E1512: f | F1512: 2 | G1512: 18623.047 | H1512: 0.020615528 | I1512: 2 | J1512: =G1512-G$2 -> 18608.771 | K1512: =D1512 -> 35.5 | L1512: =IF(E1512="e",(-1)^(D1512-0.5),(-1)^(D1512+0.5)) -> 1 | M1512: =C1512+1+VLOOKUP(B1512,states!A$2:C$10,3,FALSE) -> 2 | N1512: =J1512 -> 18608.771 | O1512: =VLOOKUP(B1512,states!A$2:C$10,2,FALSE) -> X | P1512: =C1512 -> 1 | Q1512: =VLOOKUP(B1512,states!A$2:D$10,4,FALSE) -> 1 | R1512: 0.5 | S1512: =IF(Q1512=0,R1512,IF(F1512=1,0.5,1.5)) -> 1.5 | T1512: =0.01*I1512/H1512/D1512^(1/5)*IF(P1512=0,100,1) -> 0.47510529
A1513: =B1513&"-"&D1513&"-"&E1513&"-"&C1513&"-"&F1513 -> X2Pi-35.5-f-2-1 | B1513: X2Pi | C1513: 2 | D1513: 35.5 | E1513: f | F1513: 1 | G1513: 19813.825 | H1513: 0.008660254 | I1513: 1 | J1513: =G1513-G$2 -> 19799.549 | K1513: =D1513 -> 35.5 | L1513: =IF(E1513="e",(-1)^(D1513-0.5),(-1)^(D1513+0.5)) -> 1 | M1513: =C1513+1+VLOOKUP(B1513,states!A$2:C$10,3,FALSE) -> 3 | N1513: =J1513 -> 19799.549 | O1513: =VLOOKUP(B1513,states!A$2:C$10,2,FALSE) -> X | P1513: =C1513 -> 2 | Q1513: =VLOOKUP(B1513,states!A$2:D$10,4,FALSE) -> 1 | R1513: 0.5 | S1513: =IF(Q1513=0,R1513,IF(F1513=1,0.5,1.5)) -> 0.5 | T1513: =0.01*I1513/H1513/D1513^(1/5)*IF(P1513=0,100,1) -> 0.5654884
A1514: =B1514&"-"&D1514&"-"&E1514&"-"&C1514&"-"&F1514 -> X2Pi-35.5-f-2-2 | B1514: X2Pi | C1514: 2 | D1514: 35.5 | E1514: f | F1514: 2 | G1514: 20555.649 | H1514: 0.021213203 | I1514: 1 | J1514: =G1514-G$2 -> 20541.373 | K1514: =D1514 -> 35.5 | L1514: =IF(E1514="e",(-1)^(D1514-0.5),(-1)^(D1514+0.5)) -> 1 | M1514: =C1514+1+VLOOKUP(B1514,states!A$2:C$10,3,FALSE) -> 3 | N1514: =J1514 -> 20541.373 | O1514: =VLOOKUP(B1514,states!A$2:C$10,2,FALSE) -> X | P1514: =C1514 -> 2 | Q1514: =VLOOKUP(B1514,states!A$2:D$10,4,FALSE) -> 1 | R1514: 0.5 | S1514: =IF(Q1514=0,R1514,IF(F1514=1,0.5,1.5)) -> 1.5 | T1514: =0.01*I1514/H1514/D1514^(1/5)*IF(P1514=0,100,1) -> 0.23085968
A1515: =B1515&"-"&D1515&"-"&E1515&"-"&C1515&"-"&F1515 -> X2Pi-35.5-e-1-1 | B1515: X2Pi | C1515: 1 | D1515: 35.5 | E1515: e | F1515: 1 | G1515: 17872.725 | H1515: 0.007071068 | I1515: 1 | J1515: =G1515-G$2 -> 17858.449 | K1515: =D1515 -> 35.5 | L1515: =IF(E1515="e",(-1)^(D1515-0.5),(-1)^(D1515+0.5)) -> -1 | M1515: =C1515+1+VLOOKUP(B1515,states!A$2:C$10,3,FALSE) -> 2 | N1515: =J1515 -> 17858.449 | O1515: =VLOOKUP(B1515,states!A$2:C$10,2,FALSE) -> X | P1515: =C1515 -> 1 | Q1515: =VLOOKUP(B1515,states!A$2:D$10,4,FALSE) -> 1 | R1515: 0.5 | S1515: =IF(Q1515=0,R1515,IF(F1515=1,0.5,1.5)) -> 0.5 | T1515: =0.01*I1515/H1515/D1515^(1/5)*IF(P1515=0,100,1) -> 0.69257899
A1516: =B1516&"-"&D1516&"-"&E1516&"-"&C1516&"-"&F1516 -> X2Pi-35.5-e-1-2 | B1516: X2Pi | C1516: 1 | D1516: 35.5 | E1516: e | F1516: 2 | G1516: 18592.605 | H1516: 0.020615528 | I1516: 1 | J1516: =G1516-G$2 -> 18578.329 | K1516: =D1516 -> 35.5 | L1516: =IF(E1516="e",(-1)^(D1516-0.5),(-1)^(D1516+0.5)) -> -1 | M1516: =C1516+1+VLOOKUP(B1516,states!A$2:C$10,3,FALSE) -> 2 | N1516: =J1516 -> 18578.329 | O1516: =VLOOKUP(B1516,states!A$2:C$10,2,FALSE) -> X | P1516: =C1516 -> 1 | Q1516: =VLOOKUP(B1516,states!A$2:D$10,4,FALSE) -> 1 | R1516: 0.5 | S1516: =IF(Q1516=0,R1516,IF(F1516=1,0.5,1.5)) -> 1.5 | T1516: =0.01*I1516/H1516/D1516^(1/5)*IF(P1516=0,100,1) -> 0.23755264
A1517: =B1517&"-"&D1517&"-"&E1517&"-"&C1517&"-"&F1517 -> X2Pi-35.5-e-2-1 | B1517: X2Pi | C1517: 2 | D1517: 35.5 | E1517: e | F1517: 1 | G1517: 19841.091 | H1517: 0.008660254 | I1517: 1 | J1517: =G1517-G$2 -> 19826.815 | K1517: =D1517 -> 35.5 | L1517: =IF(E1517="e",(-1)^(D1517-0.5),(-1)^(D1517+0.5)) -> -1 | M1517: =C1517+1+VLOOKUP(B1517,states!A$2:C$10,3,FALSE) -> 3 | N1517: =J1517 -> 19826.815 | O1517: =VLOOKUP(B1517,states!A$2:C$10,2,FALSE) -> X | P1517: =C1517 -> 2 | Q1517: =VLOOKUP(B1517,states!A$2:D$10,4,FALSE) -> 1 | R1517: 0.5 | S1517: =IF(Q1517=0,R1517,IF(F1517=1,0.5,1.5)) -> 0.5 | T1517: =0.01*I1517/H1517/D1517^(1/5)*IF(P1517=0,100,1) -> 0.5654884
A1518: =B1518&"-"&D1518&"-"&E1518&"-"&C1518&"-"&F1518 -> X2Pi-35.5-e-2-2 | B1518: X2Pi | C1518: 2 | D1518: 35.5 | E1518: e | F1518: 2 | G1518: 20526.6 | H1518: 0.021213203 | I1518: 1 | J1518: =G1518-G$2 -> 20512.325 | K1518: =D1518 -> 35.5 | L1518: =IF(E1518="e",(-1)^(D1518-0.5),(-1)^(D1518+0.5)) -> -1 | M1518: =C1518+1+VLOOKUP(B1518,states!A$2:C$10,3,FALSE) -> 3 | N1518: =J1518 -> 20512.325 | O1518: =VLOOKUP(B1518,states!A$2:C$10,2,FALSE) -> X | P1518: =C1518 -> 2 | Q1518: =VLOOKUP(B1518,states!A$2:D$10,4,FALSE) -> 1 | R1518: 0.5 | S1518: =IF(Q1518=0,R1518,IF(F1518=1,0.5,1.5)) -> 1.5 | T1518: =0.01*I1518/H1518/D1518^(1/5)*IF(P1518=0,100,1) -> 0.23085968
A1519: =B1519&"-"&D1519&"-"&E1519&"-"&C1519&"-"&F1519 -> A2Delta-35.5-e-0-1 | B1519: A2Delta | C1519: 0 | D1519: 35.5 | E1519: e | F1519: 1 | G1519: 39188.413 | H1519: 0.050249378 | I1519: 3 | J1519: =G1519-G$2 -> 39174.137 | K1519: =D1519 -> 35.5 | L1519: =IF(E1519="e",(-1)^(D1519-0.5),(-1)^(D1519+0.5)) -> -1 | M1519: =C1519+1+VLOOKUP(B1519,states!A$2:C$10,3,FALSE) -> 251 | N1519: =J1519 -> 39174.137 | O1519: =VLOOKUP(B1519,states!A$2:C$10,2,FALSE) -> A | P1519: =C1519 -> 0 | Q1519: =VLOOKUP(B1519,states!A$2:D$10,4,FALSE) -> 2 | R1519: 0.5 | S1519: =IF(Q1519=0,R1519,IF(F1519=1,0.5,1.5)) -> 0.5 | T1519: =0.01*I1519/H1519/D1519^(1/5)*IF(P1519=0,100,1) -> 29.237814
A1520: =B1520&"-"&D1520&"-"&E1520&"-"&C1520&"-"&F1520 -> X2Pi-36.5-e-0-1 | B1520: X2Pi | C1520: 0 | D1520: 36.5 | E1520: e | F1520: 1 | G1520: 16562.803 | H1520: 0.50251866 | I1520: 1 | J1520: =G1520-G$2 -> 16548.527 | K1520: =D1520 -> 36.5 | L1520: =IF(E1520="e",(-1)^(D1520-0.5),(-1)^(D1520+0.5)) -> 1 | M1520: =C1520+1+VLOOKUP(B1520,states!A$2:C$10,3,FALSE) -> 1 | N1520: =J1520 -> 16548.527 | O1520: =VLOOKUP(B1520,states!A$2:C$10,2,FALSE) -> X | P1520: =C1520 -> 0 | Q1520: =VLOOKUP(B1520,states!A$2:D$10,4,FALSE) -> 1 | R1520: 0.5 | S1520: =IF(Q1520=0,R1520,IF(F1520=1,0.5,1.5)) -> 0.5 | T1520: =0.01*I1520/H1520/D1520^(1/5)*IF(P1520=0,100,1) -> 0.96914607
A1521: =B1521&"-"&D1521&"-"&E1521&"-"&C1521&"-"&F1521 -> X2Pi-36.5-f-2-1 | B1521: X2Pi | C1521: 2 | D1521: 36.5 | E1521: f | F1521: 1 | G1521: 20526.648 | H1521: 0.021213203 | I1521: 1 | J1521: =G1521-G$2 -> 20512.372 | K1521: =D1521 -> 36.5 | L1521: =IF(E1521="e",(-1)^(D1521-0.5),(-1)^(D1521+0.5)) -> -1 | M1521: =C1521+1+VLOOKUP(B1521,states!A$2:C$10,3,FALSE) -> 3 | N1521: =J1521 -> 20512.372 | O1521: =VLOOKUP(B1521,states!A$2:C$10,2,FALSE) -> X | P1521: =C1521 -> 2 | Q1521: =VLOOKUP(B1521,states!A$2:D$10,4,FALSE) -> 1 | R1521: 0.5 | S1521: =IF(Q1521=0,R1521,IF(F1521=1,0.5,1.5)) -> 0.5 | T1521: =0.01*I1521/H1521/D1521^(1/5)*IF(P1521=0,100,1) -> 0.2295806
A1522: =B1522&"-"&D1522&"-"&E1522&"-"&C1522&"-"&F1522 -> X2Pi-36.5-f-2-2 | B1522: X2Pi | C1522: 2 | D1522: 36.5 | E1522: f | F1522: 2 | G1522: 21277.336 | H1522: 0.028722813 | I1522: 1 | J1522: =G1522-G$2 -> 21263.06 | K1522: =D1522 -> 36.5 | L1522: =IF(E1522="e",(-1)^(D1522-0.5),(-1)^(D1522+0.5)) -> -1 | M1522: =C1522+1+VLOOKUP(B1522,states!A$2:C$10,3,FALSE) -> 3 | N1522: =J1522 -> 21263.06 | O1522: =VLOOKUP(B1522,states!A$2:C$10,2,FALSE) -> X | P1522: =C1522 -> 2 | Q1522: =VLOOKUP(B1522,states!A$2:D$10,4,FALSE) -> 1 | R1522: 0.5 | S1522: =IF(Q1522=0,R1522,IF(F1522=1,0.5,1.5)) -> 1.5 | T1522: =0.01*I1522/H1522/D1522^(1/5)*IF(P1522=0,100,1) -> 0.16955651

Sheet MARVEL-X
A1: TAG | B1: State | C1: v | D1: J | E1: e/f | F1: F1/F2 | G1: Ener | H1: unc | I1: NCD | J1: E-ZPE | K1: J | L1: par | M1: nn | N1: E | O1: State | P1: v | Q1: Lambda | R1: Sigma | S1: Omega | T1: W
A2: =B2&"-"&D2&"-"&E2&"-"&C2&"-"&F2 -> X2Pi-0.5-e-0-2 | B2: X2Pi | C2: 0 | D2: 0.5 | E2: e | F2: 2 | G2: 0 | H2: 1e-05 | I2: 6 | J2: =G2-G$2 -> 0 | K2: =D2 -> 0.5 | L2: =E2 -> e | M2: =C2+1+VLOOKUP(B2,states!A$2:C$10,3,FALSE) -> 1 | N2: =J2 -> 0 | O2: =VLOOKUP(B2,states!A$2:C$10,2,FALSE) -> X | P2: =C2 -> 0 | Q2: =VLOOKUP(B2,states!A$2:D$10,4,FALSE) -> 1 | R2: 0.5 | S2: =IF(Q2=0,R2,IF(F2=1,0.5,1.5)) -> 1.5 | T2: =0.01*I2/H2/D2^(1/5)*IF(P2=0,100,1) -> 689219.01
A3: =B3&"-"&D3&"-"&E3&"-"&C3&"-"&F3 -> X2Pi-0.5-f-0-2 | B3: X2Pi | C3: 0 | D3: 0.5 | E3: f | F3: 2 | G3: 0.11061503 | H3: 7.78e-07 | I3: 8 | J3: =G3-G$2 -> 0.11061503 | K3: =D3 -> 0.5 | L3: =E3 -> f | M3: =C3+1+VLOOKUP(B3,states!A$2:C$10,3,FALSE) -> 1 | N3: =J3 -> 0.11061503 | O3: =VLOOKUP(B3,states!A$2:C$10,2,FALSE) -> X | P3: =C3 -> 0 | Q3: =VLOOKUP(B3,states!A$2:D$10,4,FALSE) -> 1 | R3: 0.5 | S3: =IF(Q3=0,R3,IF(F3=1,0.5,1.5)) -> 1.5 | T3: =0.01*I3/H3/D3^(1/5)*IF(P3=0,100,1) -> 11811808
A4: =B4&"-"&D4&"-"&E4&"-"&C4&"-"&F4 -> X2Pi-0.5-e-1-2 | B4: X2Pi | C4: 1 | D4: 0.5 | E4: e | F4: 2 | G4: 2731.8016 | H4: 0.001034512 | I4: 4 | J4: =G4-G$2 -> 2731.8016 | K4: =D4 -> 0.5 | L4: =E4 -> e | M4: =C4+1+VLOOKUP(B4,states!A$2:C$10,3,FALSE) -> 2 | N4: =J4 -> 2731.8016 | O4: =VLOOKUP(B4,states!A$2:C$10,2,FALSE) -> X | P4: =C4 -> 1 | Q4: =VLOOKUP(B4,states!A$2:D$10,4,FALSE) -> 1 | R4: 0.5 | S4: =IF(Q4=0,R4,IF(F4=1,0.5,1.5)) -> 1.5 | T4: =0.01*I4/H4/D4^(1/5)*IF(P4=0,100,1) -> 44.415081
A5: =B5&"-"&D5&"-"&E5&"-"&C5&"-"&F5 -> X2Pi-0.5-f-1-2 | B5: X2Pi | C5: 1 | D5: 0.5 | E5: f | F5: 2 | G5: 2731.908 | H5: 0.001034178 | I5: 4 | J5: =G5-G$2 -> 2731.908 | K5: =D5 -> 0.5 | L5: =E5 -> f | M5: =C5+1+VLOOKUP(B5,states!A$2:C$10,3,FALSE) -> 2 | N5: =J5 -> 2731.908 | O5: =VLOOKUP(B5,states!A$2:C$10,2,FALSE) -> X | P5: =C5 -> 1 | Q5: =VLOOKUP(B5,states!A$2:D$10,4,FALSE) -> 1 | R5: 0.5 | S5: =IF(Q5=0,R5,IF(F5=1,0.5,1.5)) -> 1.5 | T5: =0.01*I5/H5/D5^(1/5)*IF(P5=0,100,1) -> 44.429425
A6: =B6&"-"&D6&"-"&E6&"-"&C6&"-"&F6 -> X2Pi-0.5-e-2-2 | B6: X2Pi | C6: 2 | D6: 0.5 | E6: e | F6: 2 | G6: 5337.5964 | H6: 0.006 | I6: 2 | J6: =G6-G$2 -> 5337.5964 | K6: =D6 -> 0.5 | L6: =E6 -> e | M6: =C6+1+VLOOKUP(B6,states!A$2:C$10,3,FALSE) -> 3 | N6: =J6 -> 5337.5964 | O6: =VLOOKUP(B6,states!A$2:C$10,2,FALSE) -> X | P6: =C6 -> 2 | Q6: =VLOOKUP(B6,states!A$2:D$10,4,FALSE) -> 1 | R6: 0.5 | S6: =IF(Q6=0,R6,IF(F6=1,0.5,1.5)) -> 1.5 | T6: =0.01*I6/H6/D6^(1/5)*IF(P6=0,100,1) -> 3.8289945
A7: =B7&"-"&D7&"-"&E7&"-"&C7&"-"&F7 -> X2Pi-0.5-f-2-2 | B7: X2Pi | C7: 2 | D7: 0.5 | E7: f | F7: 2 | G7: 5337.7021 | H7: 0.006000778 | I7: 2 | J7: =G7-G$2 -> 5337.7021 | K7: =D7 -> 0.5 | L7: =E7 -> f | M7: =C7+1+VLOOKUP(B7,states!A$2:C$10,3,FALSE) -> 3 | N7: =J7 -> 5337.7021 | O7: =VLOOKUP(B7,states!A$2:C$10,2,FALSE) -> X | P7: =C7 -> 2 | Q7: =VLOOKUP(B7,states!A$2:D$10,4,FALSE) -> 1 | R7: 0.5 | S7: =IF(Q7=0,R7,IF(F7=1,0.5,1.5)) -> 1.5 | T7: =0.01*I7/H7/D7^(1/5)*IF(P7=0,100,1) -> 3.8284981
A8: =B8&"-"&D8&"-"&E8&"-"&C8&"-"&F8 -> X2Pi-0.5-f-3-2 | B8: X2Pi | C8: 3 | D8: 0.5 | E8: f | F8: 2 | G8: 7818.888 | H8: 0.021201912 | I8: 1 | J8: =G8-G$2 -> 7818.888 | K8: =D8 -> 0.5 | L8: =E8 -> f | M8: =C8+1+VLOOKUP(B8,states!A$2:C$10,3,FALSE) -> 4 | N8: =J8 -> 7818.888 | O8: =VLOOKUP(B8,states!A$2:C$10,2,FALSE) -> X | P8: =C8 -> 3 | Q8: =VLOOKUP(B8,states!A$2:D$10,4,FALSE) -> 1 | R8: 0.5 | S8: =IF(Q8=0,R8,IF(F8=1,0.5,1.5)) -> 1.5 | T8: =0.01*I8/H8/D8^(1/5)*IF(P8=0,100,1) -> 0.54178998
A9: =B9&"-"&D9&"-"&E9&"-"&C9&"-"&F9 -> X2Pi-0.5-e-4-2 | B9: X2Pi | C9: 4 | D9: 0.5 | E9: e | F9: 2 | G9: 10176.43 | H9: 0.018074178 | I9: 1 | J9: =G9-G$2 -> 10176.43 | K9: =D9 -> 0.5 | L9: =E9 -> e | M9: =C9+1+VLOOKUP(B9,states!A$2:C$10,3,FALSE) -> 5 | N9: =J9 -> 10176.43 | O9: =VLOOKUP(B9,states!A$2:C$10,2,FALSE) -> X | P9: =C9 -> 4 | Q9: =VLOOKUP(B9,states!A$2:D$10,4,FALSE) -> 1 | R9: 0.5 | S9: =IF(Q9=0,R9,IF(F9=1,0.5,1.5)) -> 1.5 | T9: =0.01*I9/H9/D9^(1/5)*IF(P9=0,100,1) -> 0.63554666
A10: =B10&"-"&D10&"-"&E10&"-"&C10&"-"&F10 -> X2Pi-1.5-f-0-1 | B10: X2Pi | C10: 0 | D10: 1.5 | E10: f | F10: 1 | G10: 17.881117 | H10: 2.1878e-05 | I10: 7 | J10: =G10-G$2 -> 17.881117 | K10: =D10 -> 1.5 | L10: =E10 -> f | M10: =C10+1+VLOOKUP(B10,states!A$2:C$10,3,FALSE) -> 1 | N10: =J10 -> 17.881117 | O10: =VLOOKUP(B10,states!A$2:C$10,2,FALSE) -> X | P10: =C10 -> 0 | Q10: =VLOOKUP(B10,states!A$2:D$10,4,FALSE) -> 1 | R10: 0.5 | S10: =IF(Q10=0,R10,IF(F10=1,0.5,1.5)) -> 0.5 | T10: =0.01*I10/H10/D10^(1/5)*IF(P10=0,100,1) -> 295034.07
A11: =B11&"-"&D11&"-"&E11&"-"&C11&"-"&F11 -> X2Pi-1.5-e-0-1 | B11: X2Pi | C11: 0 | D11: 1.5 | E11: e | F11: 1 | G11: 17.904908 | H11: 2.1883e-05 | I11: 6 | J11: =G11-G$2 -> 17.904908 | K11: =D11 -> 1.5 | L11: =E11 -> e | M11: =C11+1+VLOOKUP(B11,states!A$2:C$10,3,FALSE) -> 1 | N11: =J11 -> 17.904908 | O11: =VLOOKUP(B11,states!A$2:C$10,2,FALSE) -> X | P11: =C11 -> 0 | Q11: =VLOOKUP(B11,states!A$2:D$10,4,FALSE) -> 1 | R11: 0.5 | S11: =IF(Q11=0,R11,IF(F11=1,0.5,1.5)) -> 0.5 | T11: =0.01*I11/H11/D11^(1/5)*IF(P11=0,100,1) -> 252828.56
A12: =B12&"-"&D12&"-"&E12&"-"&C12&"-"&F12 -> X2Pi-1.5-e-0-2 | B12: X2Pi | C12: 0 | D12: 1.5 | E12: e | F12: 2 | G12: 66.939329 | H12: 3.4512e-05 | I12: 9 | J12: =G12-G$2 -> 66.939329 | K12: =D12 -> 1.5 | L12: =E12 -> e | M12: =C12+1+VLOOKUP(B12,states!A$2:C$10,3,FALSE) -> 1 | N12: =J12 -> 66.939329 | O12: =VLOOKUP(B12,states!A$2:C$10,2,FALSE) -> X | P12: =C12 -> 0 | Q12: =VLOOKUP(B12,states!A$2:D$10,4,FALSE) -> 1 | R12: 0.5 | S12: =IF(Q12=0,R12,IF(F12=1,0.5,1.5)) -> 1.5 | T12: =0.01*I12/H12/D12^(1/5)*IF(P12=0,100,1) -> 240466.25
A13: =B13&"-"&D13&"-"&E13&"-"&C13&"-"&F13 -> X2Pi-1.5-f-0-2 | B13: X2Pi | C13: 0 | D13: 1.5 | E13: f | F13: 2 | G13: 67.184059 | H13: 3.4178e-05 | I13: 9 | J13: =G13-G$2 -> 67.184059 | K13: =D13 -> 1.5 | L13: =E13 -> f | M13: =C13+1+VLOOKUP(B13,states!A$2:C$10,3,FALSE) -> 1 | N13: =J13 -> 67.184059 | O13: =VLOOKUP(B13,states!A$2:C$10,2,FALSE) -> X | P13: =C13 -> 0 | Q13: =VLOOKUP(B13,states!A$2:D$10,4,FALSE) -> 1 | R13: 0.5 | S13: =IF(Q13=0,R13,IF(F13=1,0.5,1.5)) -> 1.5 | T13: =0.01*I13/H13/D13^(1/5)*IF(P13=0,100,1) -> 242816.17
... A389: =B389&"-"&D389&"-"&E389&"-"&C389&"-"&F389 -> X2Pi-22.5-e-4-1 | B389: X2Pi | C389: 4 | D389: 22.5 | E389: e | F389: 1 | G389: 15950.608 | H389: 0.14258201 | I389: 1 | J389: =G389-G$2 -> 15950.608 | K389: =D389 -> 22.5 | L389: =E389 -> e | M389: =C389+1+VLOOKUP(B389,states!A$2:C$10,3,FALSE) -> 5 | N389: =J389 -> 15950.608 | O389: =VLOOKUP(B389,states!A$2:C$10,2,FALSE) -> X | P389: =C389 -> 4 | Q389: =VLOOKUP(B389,states!A$2:D$10,4,FALSE) -> 1 | R389: 0.5 | S389: =IF(Q389=0,R389,IF(F389=1,0.5,1.5)) -> 0.5 | T389: =0.01*I389/H389/D389^(1/5)*IF(P389=0,100,1) -> 0.037626928

Sheet PGOPHER
B1: State | C1: J | D1: e/f | F1: E | J1: state | K1: J | L1: N | M1: F | O1: E-ZPE
B2: Ground | C2: 0.5 | D2: e | E2: 1 | F2: 14.2759 | G2: 2 | H2: 0.033100975 | I2: Ground | J2: 0 | K2: 0.5 | L2: 1 | M2: F2 | N2: e | O2: =F2-F$2 -> 0
B3: Ground | C3: 0.5 | D3: f | E3: 1 | F3: 14.3867 | G3: 2 | H3: 0.033083388 | I3: Ground | J3: 0 | K3: 0.5 | L3: 1 | M3: F2 | N3: f | O3: =F3-F$2 -> 0.1108
B4: Ground | C4: 1.5 | D4: e | E4: 1 | F4: 32.1805 | G4: 4 | H4: 0.060754464 | I4: Ground | J4: 0 | K4: 1.5 | L4: 1 | M4: F1 | N4: e | O4: =F4-F$2 -> 17.9046
B5: Ground | C5: 1.5 | D5: e | E5: 2 | F5: 81.2149 | G5: 4 | H5: 0.048022775 | I5: Ground | J5: 0 | K5: 1.5 | L5: 2 | M5: F2 | N5: e | O5: =F5-F$2 -> 66.939
B6: Ground | C6: 1.5 | D6: f | E6: 1 | F6: 32.1569 | G6: 4 | H6: 0.060761352 | I6: Ground | J6: 0 | K6: 1.5 | L6: 1 | M6: F1 | N6: f | O6: =F6-F$2 -> 17.881
B7: Ground | C7: 1.5 | D7: f | E7: 2 | F7: 81.4598 | G7: 4 | H7: 0.047966415 | I7: Ground | J7: 0 | K7: 1.5 | L7: 2 | M7: F2 | N7: f | O7: =F7-F$2 -> 67.1839
B8: Ground | C8: 2.5 | D8: e | E8: 1 | F8: 87.5891 | G8: 6 | H8: 0.069865377 | I8: Ground | J8: 0 | K8: 2.5 | L8: 2 | M8: F1 | N8: e | O8: =F8-F$2 -> 73.3132
B9: Ground | C9: 2.5 | D9: e | E9: 2 | F9: 167.4705 | G9: 6 | H9: 0.04763012 | I9: Ground | J9: 0 | K9: 2.5 | L9: 3 | M9: F2 | N9: e | O9: =F9-F$2 -> 153.1946
B10: Ground | C10: 2.5 | D10: f | E10: 1 | F10: 87.4272 | G10: 6 | H10: 0.069919653 | I10: Ground | J10: 0 | K10: 2.5 | L10: 2 | M10: F1 | N10: f | O10: =F10-F$2 -> 73.1513
B11: Ground | C11: 2.5 | D11: f | E11: 2 | F11: 167.9632 | G11: 6 | H11: 0.047517705 | I11: Ground | J11: 0 | K11: 2.5 | L11: 3 | M11: F2 | N11: f | O11: =F11-F$2 -> 153.6873
B12: Ground | C12: 3.5 | D12: e | E12: 1 | F12: 172.0454 | G12: 8 | H12: 0.062128587 | I12: Ground | J12: 0 | K12: 3.5 | L12: 3 | M12: F1 | N12: e | O12: =F12-F$2 -> 157.7695
B13: Ground | C13: 3.5 | D13: e | E13: 2 | F13: 281.1217 | G13: 8 | H13: 0.03682161 | I13: Ground | J13: 0 | K13: 3.5 | L13: 4 | M13: F2 | N13: e | O13: =F13-F$2 -> 266.8458
... B157: Excited | C157: 19.5 | D157: f | E157: 2 | F157: 8232.5913 | G157: 40 | H157: 5.0513e-18 | I157: Excited | J157: 1 | K157: 19.5 | L157: 20 | M157: F2 | N157: f | O157: =F157-F$2 -> 8218.3154

Sheet states
A1: States | B1: Label | C1: shift | D1: Lambda
A2: X2Pi | B2: X | C2: 0 | D2: 1
A3: B2Sigma | B3: B | C3: 50 | D3: 0
A4: C2Sigma | B4: C | C4: 100 | D4: 0
A5: D2Pi | B5: D | C5: 150 | D5: 1
A6: E2Sigma | B6: E | C6: 200 | D6: 0
A7: A2Delta | B7: A | C7: 250 | D7: 2
A8: X2Pi-e | B8: R | C8: 10000 | D8: 1

Sheet MARVEL-trans
A1: nn | B1: nu | C1: unc | D1: State' | E1: v' | F1: J' | G1: e/f | H1: F | I1: State" | J1: v" | K1: J" | L1: e/f" | M1: F" | N1: Source | O1: minus | P1: TAG' | Q1: TAG" | R1: E' | S1: E" | T1: Esum | U1: Nsum | V1: Eave | W1: 0.05 | X1: TAG-duo | Y1: J | Z1: par | AA1: nn | AB1: E | AC1: State | AD1: v | AE1: Lambda | AF1: Sigma | AG1: Omega | AH1: W
A2: 1 | B2: 2616.2957 | C2: 0.005 | D2: X2Pi-a | E2: 3 | F2: 5.5 | G2: e | H2: 2 | I2: X2Pi | J2: 2 | K2: 4.5 | L2: e | M2: 2 | N2: 87Bernath.146 | O2: -1 | P2: =D2&"-"&F2&"-"&G2&"-"&E2&"-"&H2 -> X2Pi-a-5.5-e-3-2 | Q2: =I2&"-"&K2&"-"&L2&"-"&J2&"-"&M2 -> X2Pi-4.5-e-2-2 | R2: =B2+S2 -> 8332.9238 | S2: =_xlfn.IFNA(VLOOKUP(Q2,'MARVEL-X'!A$2:I$1400,7,FALSE),VLOOKUP(Q2,MARVEL!A$2:J$1522,10,FALSE)) -> 5716.6281 | T2: =IF(P2=P1,R2+T1,R2) -> 8332.9238 | U2: =IF(P2=P1,1+U1,1) -> 1 | V2: =IF(P2=P3,"",T2/U2) -> 8332.9238 | W2: =IF(V2="","",IF(ABS(V2-R2)>W$1,ABS(V2-R2),"")) | X2: =Y2&"-"&Z2&"-"&AC2&"-"&AD2&"-"&AG2 -> 5.5-e-XX-3-0.5 | Y2: =F2 -> 5.5 | Z2: =G2 -> e | AA2: =_xlfn.IFNA(VLOOKUP(X2,'duo-out'!A$2:Q$5000,5,FALSE),E2+10*(H2-1)+1+_xlfn.IFNA(VLOOKUP(D2,states!A$2:C$10,3,FALSE),1)) -> 15 | AB2: =IF(V2="","",V2) -> 8332.9238 | AC2: =_xlfn.IFNA(VLOOKUP(D2,states!A$2:C$10,2,FALSE),"XX") -> XX | AD2: =E2 -> 3 | AE2: =_xlfn.IFNA(VLOOKUP(D2,states!A$2:D$10,4,FALSE),0) -> 0 | AF2: 0.5 | AG2: =IF(AE2=0,AF2,IF(AE2=1,IF(F2=0.5,0.5,IF(H2=1,0.5,1.5)),IF(F2=0.5,0.5,IF(H2=1,2.5,1.5)))) -> 0.5 | AH2: =IF(AC2="XX",0,1/C2^(1/5)*IF(E2=0,100,1)/(E2+1)^(1/4)) -> 0
A3: 1642 | B3: 2664.8854 | C3: 0.01085 | D3: X2Pi | E3: 1 | F3: 0.5 | G3: e | H3: 2 | I3: X2Pi | J3: 0 | K3: 1.5 | L3: e | M3: 2 | N3: 87Bernath.52 | O3: 1 | P3: =D3&"-"&F3&"-"&G3&"-"&E3&"-"&H3 -> X2Pi-0.5-e-1-2 | Q3: =I3&"-"&K3&"-"&L3&"-"&J3&"-"&M3 -> X2Pi-1.5-e-0-2 | R3: =B3+S3 -> 2731.8247 | S3: =_xlfn.IFNA(VLOOKUP(Q3,'MARVEL-X'!A$2:I$1400,7,FALSE),VLOOKUP(Q3,MARVEL!A$2:J$1522,10,FALSE)) -> 66.939329 | T3: =IF(P3=P2,R3+T2,R3) -> 2731.8247 | U3: =IF(P3=P2,1+U2,1) -> 1 | V3: =IF(P3=P4,"",T3/U3) | W3: =IF(V3="","",IF(ABS(V3-R3)>W$1,ABS(V3-R3),"")) | X3: =Y3&"-"&Z3&"-"&AC3&"-"&AD3&"-"&AG3 -> 0.5-e-X-1-0.5 | Y3: =F3 -> 0.5 | Z3: =G3 -> e | AA3: =_xlfn.IFNA(VLOOKUP(X3,'duo-out'!A$2:Q$5000,5,FALSE),E3+10*(H3-1)+1+_xlfn.IFNA(VLOOKUP(D3,states!A$2:C$10,3,FALSE),1)) -> 2 | AB3: =IF(V3="","",V3) | AC3: =_xlfn.IFNA(VLOOKUP(D3,states!A$2:C$10,2,FALSE),"XX") -> X | AD3: =E3 -> 1 | AE3: =_xlfn.IFNA(VLOOKUP(D3,states!A$2:D$10,4,FALSE),0) -> 1 | AF3: 0.5 | AG3: =IF(AE3=0,AF3,IF(AE3=1,IF(F3=0.5,0.5,IF(H3=1,0.5,1.5)),IF(F3=0.5,0.5,IF(H3=1,2.5,1.5)))) -> 0.5 | AH3: =IF(AC3="XX",0,1/C3^(1/5)*IF(E3=0,100,1)/(E3+1)^(1/4)) -> 2.0780527
A4: 1924 | B4: 2664.8618 | C4: 0.001 | D4: X2Pi | E4: 1 | F4: 0.5 | G4: e | H4: 2 | I4: X2Pi | J4: 0 | K4: 1.5 | L4: e | M4: 2 | N4: 84LuAm.14 | O4: 1 | P4: =D4&"-"&F4&"-"&G4&"-"&E4&"-"&H4 -> X2Pi-0.5-e-1-2 | Q4: =I4&"-"&K4&"-"&L4&"-"&J4&"-"&M4 -> X2Pi-1.5-e-0-2 | R4: =B4+S4 -> 2731.8011 | S4: =_xlfn.IFNA(VLOOKUP(Q4,'MARVEL-X'!A$2:I$1400,7,FALSE),VLOOKUP(Q4,MARVEL!A$2:J$1522,10,FALSE)) -> 66.939329 | T4: =IF(P4=P3,R4+T3,R4) -> 5463.6259 | U4: =IF(P4=P3,1+U3,1) -> 2 | V4: =IF(P4=P5,"",T4/U4) -> 2731.8129 | W4: =IF(V4="","",IF(ABS(V4-R4)>W$1,ABS(V4-R4),"")) | X4: =Y4&"-"&Z4&"-"&AC4&"-"&AD4&"-"&AG4 -> 0.5-e-X-1-0.5 | Y4: =F4 -> 0.5 | Z4: =G4 -> e | AA4: =_xlfn.IFNA(VLOOKUP(X4,'duo-out'!A$2:Q$5000,5,FALSE),E4+10*(H4-1)+1+_xlfn.IFNA(VLOOKUP(D4,states!A$2:C$10,3,FALSE),1)) -> 2 | AB4: =IF(V4="","",V4) -> 2731.8129 | AC4: =_xlfn.IFNA(VLOOKUP(D4,states!A$2:C$10,2,FALSE),"XX") -> X | AD4: =E4 -> 1 | AE4: =_xlfn.IFNA(VLOOKUP(D4,states!A$2:D$10,4,FALSE),0) -> 1 | AF4: 0.5 | AG4: =IF(AE4=0,AF4,IF(AE4=1,IF(F4=0.5,0.5,IF(H4=1,0.5,1.5)),IF(F4=0.5,0.5,IF(H4=1,2.5,1.5)))) -> 0.5 | AH4: =IF(AC4="XX",0,1/C4^(1/5)*IF(E4=0,100,1)/(E4+1)^(1/4)) -> 3.3476689
A5: 1706 | B5: 2540.7135 | C5: 0.005 | D5: X2Pi | E5: 2 | F5: 0.5 | G5: e | H5: 2 | I5: X2Pi | J5: 1 | K5: 1.5 | L5: e | M5: 2 | N5: 87Bernath.116 | O5: 1 | P5: =D5&"-"&F5&"-"&G5&"-"&E5&"-"&H5 -> X2Pi-0.5-e-2-2 | Q5: =I5&"-"&K5&"-"&L5&"-"&J5&"-"&M5 -> X2Pi-1.5-e-1-2 | R5: =B5+S5 -> 5337.5992 | S5: =_xlfn.IFNA(VLOOKUP(Q5,'MARVEL-X'!A$2:I$1400,7,FALSE),VLOOKUP(Q5,MARVEL!A$2:J$1522,10,FALSE)) -> 2796.8857 | T5: =IF(P5=P4,R5+T4,R5) -> 5337.5992 | U5: =IF(P5=P4,1+U4,1) -> 1 | V5: =IF(P5=P6,"",T5/U5) | W5: =IF(V5="","",IF(ABS(V5-R5)>W$1,ABS(V5-R5),"")) | X5: =Y5&"-"&Z5&"-"&AC5&"-"&AD5&"-"&AG5 -> 0.5-e-X-2-0.5 | Y5: =F5 -> 0.5 | Z5: =G5 -> e | AA5: =_xlfn.IFNA(VLOOKUP(X5,'duo-out'!A$2:Q$5000,5,FALSE),E5+10*(H5-1)+1+_xlfn.IFNA(VLOOKUP(D5,states!A$2:C$10,3,FALSE),1)) -> 4 | AB5: =IF(V5="","",V5) | AC5: =_xlfn.IFNA(VLOOKUP(D5,states!A$2:C$10,2,FALSE),"XX") -> X | AD5: =E5 -> 2 | AE5: =_xlfn.IFNA(VLOOKUP(D5,states!A$2:D$10,4,FALSE),0) -> 1 | AF5: 0.5 | AG5: =IF(AE5=0,AF5,IF(AE5=1,IF(F5=0.5,0.5,IF(H5=1,0.5,1.5)),IF(F5=0.5,0.5,IF(H5=1,2.5,1.5)))) -> 0.5 | AH5: =IF(AC5="XX",0,1/C5^(1/5)*IF(E5=0,100,1)/(E5+1)^(1/4)) -> 2.1924297
A6: 1769 | B6: 2605.6856 | C6: 0.005 | D6: X2Pi | E6: 2 | F6: 0.5 | G6: e | H6: 2 | I6: X2Pi | J6: 1 | K6: 0.5 | L6: f | M6: 2 | N6: 87Bernath.180 | O6: 1 | P6: =D6&"-"&F6&"-"&G6&"-"&E6&"-"&H6 -> X2Pi-0.5-e-2-2 | Q6: =I6&"-"&K6&"-"&L6&"-"&J6&"-"&M6 -> X2Pi-0.5-f-1-2 | R6: =B6+S6 -> 5337.5936 | S6: =_xlfn.IFNA(VLOOKUP(Q6,'MARVEL-X'!A$2:I$1400,7,FALSE),VLOOKUP(Q6,MARVEL!A$2:J$1522,10,FALSE)) -> 2731.908 | T6: =IF(P6=P5,R6+T5,R6) -> 10675.193 | U6: =IF(P6=P5,1+U5,1) -> 2 | V6: =IF(P6=P7,"",T6/U6) -> 5337.5964 | W6: =IF(V6="","",IF(ABS(V6-R6)>W$1,ABS(V6-R6),"")) | X6: =Y6&"-"&Z6&"-"&AC6&"-"&AD6&"-"&AG6 -> 0.5-e-X-2-0.5 | Y6: =F6 -> 0.5 | Z6: =G6 -> e | AA6: =_xlfn.IFNA(VLOOKUP(X6,'duo-out'!A$2:Q$5000,5,FALSE),E6+10*(H6-1)+1+_xlfn.IFNA(VLOOKUP(D6,states!A$2:C$10,3,FALSE),1)) -> 4 | AB6: =IF(V6="","",V6) -> 5337.5964 | AC6: =_xlfn.IFNA(VLOOKUP(D6,states!A$2:C$10,2,FALSE),"XX") -> X | AD6: =E6 -> 2 | AE6: =_xlfn.IFNA(VLOOKUP(D6,states!A$2:D$10,4,FALSE),0) -> 1 | AF6: 0.5 | AG6: =IF(AE6=0,AF6,IF(AE6=1,IF(F6=0.5,0.5,IF(H6=1,0.5,1.5)),IF(F6=0.5,0.5,IF(H6=1,2.5,1.5)))) -> 0.5 | AH6: =IF(AC6="XX",0,1/C6^(1/5)*IF(E6=0,100,1)/(E6+1)^(1/4)) -> 2.1924297
A7: 2609 | B7: 2296.2426 | C7: 0.005 | D7: X2Pi | E7: 4 | F7: 0.5 | G7: e | H7: 2 | I7: X2Pi | J7: 3 | K7: 1.5 | L7: e | M7: 2 | N7: 91BeBrOlHa.37 | O7: 1 | P7: =D7&"-"&F7&"-"&G7&"-"&E7&"-"&H7 -> X2Pi-0.5-e-4-2 | Q7: =I7&"-"&K7&"-"&L7&"-"&J7&"-"&M7 -> X2Pi-1.5-e-3-2 | R7: =B7+S7 -> 10176.43 | S7: =_xlfn.IFNA(VLOOKUP(Q7,'MARVEL-X'!A$2:I$1400,7,FALSE),VLOOKUP(Q7,MARVEL!A$2:J$1522,10,FALSE)) -> 7880.1875 | T7: =IF(P7=P6,R7+T6,R7) -> 10176.43 | U7: =IF(P7=P6,1+U6,1) -> 1 | V7: =IF(P7=P8,"",T7/U7) -> 10176.43 | W7: =IF(V7="","",IF(ABS(V7-R7)>W$1,ABS(V7-R7),"")) | X7: =Y7&"-"&Z7&"-"&AC7&"-"&AD7&"-"&AG7 -> 0.5-e-X-4-0.5 | Y7: =F7 -> 0.5 | Z7: =G7 -> e | AA7: =_xlfn.IFNA(VLOOKUP(X7,'duo-out'!A$2:Q$5000,5,FALSE),E7+10*(H7-1)+1+_xlfn.IFNA(VLOOKUP(D7,states!A$2:C$10,3,FALSE),1)) -> 8 | AB7: =IF(V7="","",V7) -> 10176.43 | AC7: =_xlfn.IFNA(VLOOKUP(D7,states!A$2:C$10,2,FALSE),"XX") -> X | AD7: =E7 -> 4 | AE7: =_xlfn.IFNA(VLOOKUP(D7,states!A$2:D$10,4,FALSE),0) -> 1 | AF7: 0.5 | AG7: =IF(AE7=0,AF7,IF(AE7=1,IF(F7=0.5,0.5,IF(H7=1,0.5,1.5)),IF(F7=0.5,0.5,IF(H7=1,2.5,1.5)))) -> 0.5 | AH7: =IF(AC7="XX",0,1/C7^(1/5)*IF(E7=0,100,1)/(E7+1)^(1/4)) -> 1.9295832
A8: 2569 | B8: 0.11062242 | C8: 0.000169 | D8: X2Pi | E8: 0 | F8: 0.5 | G8: f | H8: 2 | I8: X2Pi | J8: 0 | K8: 0.5 | L8: e | M8: 2 | N8: 85StWoBr.1 | O8: 1 | P8: =D8&"-"&F8&"-"&G8&"-"&E8&"-"&H8 -> X2Pi-0.5-f-0-2 | Q8: =I8&"-"&K8&"-"&L8&"-"&J8&"-"&M8 -> X2Pi-0.5-e-0-2 | R8: =B8+S8 -> 0.11062242 | S8: =_xlfn.IFNA(VLOOKUP(Q8,'MARVEL-X'!A$2:I$1400,7,FALSE),VLOOKUP(Q8,MARVEL!A$2:J$1522,10,FALSE)) -> 0 | T8: =IF(P8=P7,R8+T7,R8) -> 0.11062242 | U8: =IF(P8=P7,1+U7,1) -> 1 | V8: =IF(P8=P9,"",T8/U8) | W8: =IF(V8="","",IF(ABS(V8-R8)>W$1,ABS(V8-R8),"")) | X8: =Y8&"-"&Z8&"-"&AC8&"-"&AD8&"-"&AG8 -> 0.5-f-X-0-0.5 | Y8: =F8 -> 0.5 | Z8: =G8 -> f | AA8: =_xlfn.IFNA(VLOOKUP(X8,'duo-out'!A$2:Q$5000,5,FALSE),E8+10*(H8-1)+1+_xlfn.IFNA(VLOOKUP(D8,states!A$2:C$10,3,FALSE),1)) -> 1 | AB8: =IF(V8="","",V8) | AC8: =_xlfn.IFNA(VLOOKUP(D8,states!A$2:C$10,2,FALSE),"XX") -> X | AD8: =E8 -> 0 | AE8: =_xlfn.IFNA(VLOOKUP(D8,states!A$2:D$10,4,FALSE),0) -> 1 | AF8: 0.5 | AG8: =IF(AE8=0,AF8,IF(AE8=1,IF(F8=0.5,0.5,IF(H8=1,0.5,1.5)),IF(F8=0.5,0.5,IF(H8=1,2.5,1.5)))) -> 0.5 | AH8: =IF(AC8="XX",0,1/C8^(1/5)*IF(E8=0,100,1)/(E8+1)^(1/4)) -> 568.09721
A9: 2567 | B9: 0.11061503 | C9: 1e-09 | D9: X2Pi | E9: 0 | F9: 0.5 | G9: f | H9: 2 | I9: X2Pi | J9: 0 | K9: 0.5 | L9: e | M9: 2 | N9: 13TrHeHiTa.1 | O9: 1 | P9: =D9&"-"&F9&"-"&G9&"-"&E9&"-"&H9 -> X2Pi-0.5-f-0-2 | Q9: =I9&"-"&K9&"-"&L9&"-"&J9&"-"&M9 -> X2Pi-0.5-e-0-2 | R9: =B9+S9 -> 0.11061503 | S9: =_xlfn.IFNA(VLOOKUP(Q9,'MARVEL-X'!A$2:I$1400,7,FALSE),VLOOKUP(Q9,MARVEL!A$2:J$1522,10,FALSE)) -> 0 | T9: =IF(P9=P8,R9+T8,R9) -> 0.22123745 | U9: =IF(P9=P8,1+U8,1) -> 2 | V9: =IF(P9=P10,"",T9/U9) | W9: =IF(V9="","",IF(ABS(V9-R9)>W$1,ABS(V9-R9),"")) | X9: =Y9&"-"&Z9&"-"&AC9&"-"&AD9&"-"&AG9 -> 0.5-f-X-0-0.5 | Y9: =F9 -> 0.5 | Z9: =G9 -> f | AA9: =_xlfn.IFNA(VLOOKUP(X9,'duo-out'!A$2:Q$5000,5,FALSE),E9+10*(H9-1)+1+_xlfn.IFNA(VLOOKUP(D9,states!A$2:C$10,3,FALSE),1)) -> 1 | AB9: =IF(V9="","",V9) | AC9: =_xlfn.IFNA(VLOOKUP(D9,states!A$2:C$10,2,FALSE),"XX") -> X | AD9: =E9 -> 0 | AE9: =_xlfn.IFNA(VLOOKUP(D9,states!A$2:D$10,4,FALSE),0) -> 1 | AF9: 0.5 | AG9: =IF(AE9=0,AF9,IF(AE9=1,IF(F9=0.5,0.5,IF(H9=1,0.5,1.5)),IF(F9=0.5,0.5,IF(H9=1,2.5,1.5)))) -> 0.5 | AH9: =IF(AC9="XX",0,1/C9^(1/5)*IF(E9=0,100,1)/(E9+1)^(1/4)) -> 6309.5734
A10: 2564 | B10: 0.11061508 | C10: 7.783e-07 | D10: X2Pi | E10: 0 | F10: 0.5 | G10: f | H10: 2 | I10: X2Pi | J10: 0 | K10: 0.5 | L10: e | M10: 2 | N10: 06McMoBrTh.1 | O10: 1 | P10: =D10&"-"&F10&"-"&G10&"-"&E10&"-"&H10 -> X2Pi-0.5-f-0-2 | Q10: =I10&"-"&K10&"-"&L10&"-"&J10&"-"&M10 -> X2Pi-0.5-e-0-2 | R10: =B10+S10 -> 0.11061508 | S10: =_xlfn.IFNA(VLOOKUP(Q10,'MARVEL-X'!A$2:I$1400,7,FALSE),VLOOKUP(Q10,MARVEL!A$2:J$1522,10,FALSE)) -> 0 | T10: =IF(P10=P9,R10+T9,R10) -> 0.33185253 | U10: =IF(P10=P9,1+U9,1) -> 3 | V10: =IF(P10=P11,"",T10/U10) -> 0.11061751 | W10: =IF(V10="","",IF(ABS(V10-R10)>W$1,ABS(V10-R10),"")) | X10: =Y10&"-"&Z10&"-"&AC10&"-"&AD10&"-"&AG10 -> 0.5-f-X-0-0.5 | Y10: =F10 -> 0.5 | Z10: =G10 -> f | AA10: =_xlfn.IFNA(VLOOKUP(X10,'duo-out'!A$2:Q$5000,5,FALSE),E10+10*(H10-1)+1+_xlfn.IFNA(VLOOKUP(D10,states!A$2:C$10,3,FALSE),1)) -> 1 | AB10: =IF(V10="","",V10) -> 0.11061751 | AC10: =_xlfn.IFNA(VLOOKUP(D10,states!A$2:C$10,2,FALSE),"XX") -> X | AD10: =E10 -> 0 | AE10: =_xlfn.IFNA(VLOOKUP(D10,states!A$2:D$10,4,FALSE),0) -> 1 | AF10: 0.5 | AG10: =IF(AE10=0,AF10,IF(AE10=1,IF(F10=0.5,0.5,IF(H10=1,0.5,1.5)),IF(F10=0.5,0.5,IF(H10=1,2.5,1.5)))) -> 0.5 | AH10: =IF(AC10="XX",0,1/C10^(1/5)*IF(E10=0,100,1)/(E10+1)^(1/4)) -> 1666.3668
A11: 1650 | B11: 2664.7423 | C11: 0.005 | D11: X2Pi | E11: 1 | F11: 0.5 | G11: f | H11: 2 | I11: X2Pi | J11: 0 | K11: 1.5 | L11: f | M11: 2 | N11: 87Bernath.60 | O11: 1 | P11: =D11&"-"&F11&"-"&G11&"-"&E11&"-"&H11 -> X2Pi-0.5-f-1-2 | Q11: =I11&"-"&K11&"-"&L11&"-"&J11&"-"&M11 -> X2Pi-1.5-f-0-2 | R11: =B11+S11 -> 2731.9264 | S11: =_xlfn.IFNA(VLOOKUP(Q11,'MARVEL-X'!A$2:I$1400,7,FALSE),VLOOKUP(Q11,MARVEL!A$2:J$1522,10,FALSE)) -> 67.184059 | T11: =IF(P11=P10,R11+T10,R11) -> 2731.9264 | U11: =IF(P11=P10,1+U10,1) -> 1 | V11: =IF(P11=P12,"",T11/U11) | W11: =IF(V11="","",IF(ABS(V11-R11)>W$1,ABS(V11-R11),"")) | X11: =Y11&"-"&Z11&"-"&AC11&"-"&AD11&"-"&AG11 -> 0.5-f-X-1-0.5 | Y11: =F11 -> 0.5 | Z11: =G11 -> f | AA11: =_xlfn.IFNA(VLOOKUP(X11,'duo-out'!A$2:Q$5000,5,FALSE),E11+10*(H11-1)+1+_xlfn.IFNA(VLOOKUP(D11,states!A$2:C$10,3,FALSE),1)) -> 2 | AB11: =IF(V11="","",V11) | AC11: =_xlfn.IFNA(VLOOKUP(D11,states!A$2:C$10,2,FALSE),"XX") -> X | AD11: =E11 -> 1 | AE11: =_xlfn.IFNA(VLOOKUP(D11,states!A$2:D$10,4,FALSE),0) -> 1 | AF11: 0.5 | AG11: =IF(AE11=0,AF11,IF(AE11=1,IF(F11=0.5,0.5,IF(H11=1,0.5,1.5)),IF(F11=0.5,0.5,IF(H11=1,2.5,1.5)))) -> 0.5 | AH11: =IF(AC11="XX",0,1/C11^(1/5)*IF(E11=0,100,1)/(E11+1)^(1/4)) -> 2.4263224
A12: 1923 | B12: 2664.7229 | C12: 0.001 | D12: X2Pi | E12: 1 | F12: 0.5 | G12: f | H12: 2 | I12: X2Pi | J12: 0 | K12: 1.5 | L12: f | M12: 2 | N12: 84LuAm.13 | O12: 1 | P12: =D12&"-"&F12&"-"&G12&"-"&E12&"-"&H12 -> X2Pi-0.5-f-1-2 | Q12: =I12&"-"&K12&"-"&L12&"-"&J12&"-"&M12 -> X2Pi-1.5-f-0-2 | R12: =B12+S12 -> 2731.907 | S12: =_xlfn.IFNA(VLOOKUP(Q12,'MARVEL-X'!A$2:I$1400,7,FALSE),VLOOKUP(Q12,MARVEL!A$2:J$1522,10,FALSE)) -> 67.184059 | T12: =IF(P12=P11,R12+T11,R12) -> 5463.8333 | U12: =IF(P12=P11,1+U11,1) -> 2 | V12: =IF(P12=P13,"",T12/U12) -> 2731.9167 | W12: =IF(V12="","",IF(ABS(V12-R12)>W$1,ABS(V12-R12),"")) | X12: =Y12&"-"&Z12&"-"&AC12&"-"&AD12&"-"&AG12 -> 0.5-f-X-1-0.5 | Y12: =F12 -> 0.5 | Z12: =G12 -> f | AA12: =_xlfn.IFNA(VLOOKUP(X12,'duo-out'!A$2:Q$5000,5,FALSE),E12+10*(H12-1)+1+_xlfn.IFNA(VLOOKUP(D12,states!A$2:C$10,3,FALSE),1)) -> 2 | AB12: =IF(V12="","",V12) -> 2731.9167 | AC12: =_xlfn.IFNA(VLOOKUP(D12,states!A$2:C$10,2,FALSE),"XX") -> X | AD12: =E12 -> 1 | AE12: =_xlfn.IFNA(VLOOKUP(D12,states!A$2:D$10,4,FALSE),0) -> 1 | AF12: 0.5 | AG12: =IF(AE12=0,AF12,IF(AE12=1,IF(F12=0.5,0.5,IF(H12=1,0.5,1.5)),IF(F12=0.5,0.5,IF(H12=1,2.5,1.5)))) -> 0.5 | AH12: =IF(AC12="XX",0,1/C12^(1/5)*IF(E12=0,100,1)/(E12+1)^(1/4)) -> 3.3476689
A13: 1712 | B13: 2540.5856 | C13: 0.005 | D13: X2Pi | E13: 2 | F13: 0.5 | G13: f | H13: 2 | I13: X2Pi | J13: 1 | K13: 1.5 | L13: f | M13: 2 | N13: 87Bernath.122 | O13: 1 | P13: =D13&"-"&F13&"-"&G13&"-"&E13&"-"&H13 -> X2Pi-0.5-f-2-2 | Q13: =I13&"-"&K13&"-"&L13&"-"&J13&"-"&M13 -> X2Pi-1.5-f-1-2 | R13: =B13+S13 -> 5337.7042 | S13: =_xlfn.IFNA(VLOOKUP(Q13,'MARVEL-X'!A$2:I$1400,7,FALSE),VLOOKUP(Q13,MARVEL!A$2:J$1522,10,FALSE)) -> 2797.1186 | T13: =IF(P13=P12,R13+T12,R13) -> 5337.7042 | U13: =IF(P13=P12,1+U12,1) -> 1 | V13: =IF(P13=P14,"",T13/U13) | W13: =IF(V13="","",IF(ABS(V13-R13)>W$1,ABS(V13-R13),"")) | X13: =Y13&"-"&Z13&"-"&AC13&"-"&AD13&"-"&AG13 -> 0.5-f-X-2-0.5 | Y13: =F13 -> 0.5 | Z13: =G13 -> f | AA13: =_xlfn.IFNA(VLOOKUP(X13,'duo-out'!A$2:Q$5000,5,FALSE),E13+10*(H13-1)+1+_xlfn.IFNA(VLOOKUP(D13,states!A$2:C$10,3,FALSE),1)) -> 4 | AB13: =IF(V13="","",V13) | AC13: =_xlfn.IFNA(VLOOKUP(D13,states!A$2:C$10,2,FALSE),"XX") -> X | AD13: =E13 -> 2 | AE13: =_xlfn.IFNA(VLOOKUP(D13,states!A$2:D$10,4,FALSE),0) -> 1 | AF13: 0.5 | AG13: =IF(AE13=0,AF13,IF(AE13=1,IF(F13=0.5,0.5,IF(H13=1,0.5,1.5)),IF(F13=0.5,0.5,IF(H13=1,2.5,1.5)))) -> 0.5 | AH13: =IF(AC13="XX",0,1/C13^(1/5)*IF(E13=0,100,1)/(E13+1)^(1/4)) -> 2.1924297
... A3711: 1344 | B3711: 23280.93 | C3711: 0.05 | D3711: A2Delta | E3711: 2 | F3711: 5.5 | G3711: e | H3711: 2 | I3711: X2Pi | J3711: 2 | K3711: 4.5 | L3711: e | M3711: 2 | N3711: 41Gero.1003 | O3711: 1 | P3711: =D3711&"-"&F3711&"-"&G3711&"-"&E3711&"-"&H3711 -> A2Delta-5.5-e-2-2 | Q3711: =I3711&"-"&K3711&"-"&L3711&"-"&J3711&"-"&M3711 -> X2Pi-4.5-e-2-2 | R3711: =B3711+S3711 -> 28997.558 | S3711: =_xlfn.IFNA(VLOOKUP(Q3711,'MARVEL-X'!A$2:I$1400,7,FALSE),VLOOKUP(Q3711,MARVEL!A$2:J$1522,10,FALSE)) -> 5716.6281 | T3711: =IF(P3711=P3710,R3711+T3710,R3711) -> 289975.64 | U3711: =IF(P3711=P3710,1+U3710,1) -> 10 | V3711: =IF(P3711=P3712,"",T3711/U3711) | W3711: =IF(V3711="","",IF(ABS(V3711-R3711)>W$1,ABS(V3711-R3711),"")) | X3711: =Y3711&"-"&Z3711&"-"&AC3711&"-"&AD3711&"-"&AG3711 -> 5.5-e-A-2-1.5 | Y3711: =F3711 -> 5.5 | Z3711: =G3711 -> e | AA3711: =_xlfn.IFNA(VLOOKUP(X3711,'duo-out'!A$2:Q$5000,5,FALSE),E3711+10*(H3711-1)+1+_xlfn.IFNA(VLOOKUP(D3711,states!A$2:C$10,3,FALSE),1)) -> 86 | AB3711: =IF(V3711="","",V3711) | AC3711: =_xlfn.IFNA(VLOOKUP(D3711,states!A$2:C$10,2,FALSE),"XX") -> A | AD3711: =E3711 -> 2 | AE3711: =_xlfn.IFNA(VLOOKUP(D3711,states!A$2:D$10,4,FALSE),0) -> 2 | AF3711: 0.5 | AG3711: =IF(AE3711=0,AF3711,IF(AE3711=1,IF(F3711=0.5,0.5,IF(H3711=1,0.5,1.5)),IF(F3711=0.5,0.5,IF(H3711=1,2.5,1.5)))) -> 1.5 | AH3711: =IF(AC3711="XX",0,1/C3711^(1/5)*IF(E3711=0,100,1)/(E3711+1)^(1/4)) -> 1.3833296
A3712: 23 | B3712: 20814.177 | C3712: 0.005 | D3712: A2Delta | E3712: 2 | F3712: 5.5 | G3712: e | H3712: 2 | I3712: X2Pi | J3712: 3 | K3712: 4.5 | L3712: e | M3712: 2 | N3712: 95Zachwiej.999 | O3712: -1 | P3712: =D3712&"-"&F3712&"-"&G3712&"-"&E3712&"-"&H3712 -> A2Delta-5.5-e-2-2 | Q3712: =I3712&"-"&K3712&"-"&L3712&"-"&J3712&"-"&M3712 -> X2Pi-4.5-e-3-2 | R3712: =B3712+S3712 -> 28997.556 | S3712: =_xlfn.IFNA(VLOOKUP(Q3712,'MARVEL-X'!A$2:I$1400,7,FALSE),VLOOKUP(Q3712,MARVEL!A$2:J$1522,10,FALSE)) -> 8183.3788 | T3712: =IF(P3712='95Zachwiej'!P138,R3712+'95Zachwiej'!T138,R3712) -> 28997.556 | U3712: =IF(P3712='95Zachwiej'!P138,1+'95Zachwiej'!U138,1) -> 1 | V3712: =IF(P3712=P3713,"",T3712/U3712) -> 28997.556 | W3712: =IF(V3712="","",IF(ABS(V3712-R3712)>W$1,ABS(V3712-R3712),"")) | X3712: =Y3712&"-"&Z3712&"-"&AC3712&"-"&AD3712&"-"&AG3712 -> 5.5-e-A-2-1.5 | Y3712: =F3712 -> 5.5 | Z3712: =G3712 -> e | AA3712: =_xlfn.IFNA(VLOOKUP(X3712,'duo-out'!A$2:Q$5000,5,FALSE),E3712+10*(H3712-1)+1+_xlfn.IFNA(VLOOKUP(D3712,states!A$2:C$10,3,FALSE),1)) -> 86 | AB3712: =IF(V3712="","",V3712) -> 28997.556 | AC3712: =_xlfn.IFNA(VLOOKUP(D3712,states!A$2:C$10,2,FALSE),"XX") -> A | AD3712: =E3712 -> 2 | AE3712: =_xlfn.IFNA(VLOOKUP(D3712,states!A$2:D$10,4,FALSE),0) -> 2 | AF3712: 0.5 | AG3712: =IF(AE3712=0,AF3712,IF(AE3712=1,IF(F3712=0.5,0.5,IF(H3712=1,0.5,1.5)),IF(F3712=0.5,0.5,IF(H3712=1,2.5,1.5)))) -> 1.5 | AH3712: =IF(AC3712="XX",0,1/C3712^(1/5)*IF(E3712=0,100,1)/(E3712+1)^(1/4)) -> 2.1924297
A3713: 3776 | B3713: 22812.7 | C3713: 0.005 | D3713: A2Delta | E3713: 3 | F3713: 5.5 | G3713: e | H3713: 1 | I3713: X2Pi | J3713: 3 | K3713: 6.5 | L3713: e | M3713: 1 | N3713: 95Zachwiej.644 | O3713: 1 | P3713: =D3713&"-"&F3713&"-"&G3713&"-"&E3713&"-"&H3713 -> A2Delta-5.5-e-3-1 | Q3713: =I3713&"-"&K3713&"-"&L3713&"-"&J3713&"-"&M3713 -> X2Pi-6.5-e-3-1 | R3713: =B3713+S3713 -> 31149.414 | S3713: =_xlfn.IFNA(VLOOKUP(Q3713,'MARVEL-X'!A$2:I$1400,7,FALSE),VLOOKUP(Q3713,MARVEL!A$2:J$1522,10,FALSE)) -> 8336.7139 | T3713: =IF(P3713=P3712,R3713+T3712,R3713) -> 31149.414 | U3713: =IF(P3713=P3712,1+U3712,1) -> 1 | V3713: =IF(P3713=P3714,"",T3713/U3713) | W3713: =IF(V3713="","",IF(ABS(V3713-R3713)>W$1,ABS(V3713-R3713),"")) | X3713: =Y3713&"-"&Z3713&"-"&AC3713&"-"&AD3713&"-"&AG3713 -> 5.5-e-A-3-2.5 | Y3713: =F3713 -> 5.5 | Z3713: =G3713 -> e | AA3713: =_xlfn.IFNA(VLOOKUP(X3713,'duo-out'!A$2:Q$5000,5,FALSE),E3713+10*(H3713-1)+1+_xlfn.IFNA(VLOOKUP(D3713,states!A$2:C$10,3,FALSE),1)) -> 109 | AB3713: =IF(V3713="","",V3713) | AC3713: =_xlfn.IFNA(VLOOKUP(D3713,states!A$2:C$10,2,FALSE),"XX") -> A | AD3713: =E3713 -> 3 | AE3713: =_xlfn.IFNA(VLOOKUP(D3713,states!A$2:D$10,4,FALSE),0) -> 2 | AF3713: 0.5 | AG3713: =IF(AE3713=0,AF3713,IF(AE3713=1,IF(F3713=0.5,0.5,IF(H3713=1,0.5,1.5)),IF(F3713=0.5,0.5,IF(H3713=1,2.5,1.5)))) -> 2.5 | AH3713: =IF(AC3713="XX",0,1/C3713^(1/5)*IF(E3713=0,100,1)/(E3713+1)^(1/4)) -> 2.0402858
A3714: 3769 | B3714: 22963.8 | C3714: 0.005 | D3714: A2Delta | E3714: 3 | F3714: 5.5 | G3714: e | H3714: 1 | I3714: X2Pi | J3714: 3 | K3714: 5.5 | L3714: f | M3714: 1 | N3714: 95Zachwiej.637 | O3714: 1 | P3714: =D3714&"-"&F3714&"-"&G3714&"-"&E3714&"-"&H3714 -> A2Delta-5.5-e-3-1 | Q3714: =I3714&"-"&K3714&"-"&L3714&"-"&J3714&"-"&M3714 -> X2Pi-5.5-f-3-1 | R3714: =B3714+S3714 -> 31149.412 | S3714: =_xlfn.IFNA(VLOOKUP(Q3714,'MARVEL-X'!A$2:I$1400,7,FALSE),VLOOKUP(Q3714,MARVEL!A$2:J$1522,10,FALSE)) -> 8185.6125 | T3714: =IF(P3714=P3713,R3714+T3713,R3714) -> 62298.826 | U3714: =IF(P3714=P3713,1+U3713,1) -> 2 | V3714: =IF(P3714=P3715,"",T3714/U3714) -> 31149.413 | W3714: =IF(V3714="","",IF(ABS(V3714-R3714)>W$1,ABS(V3714-R3714),"")) | X3714: =Y3714&"-"&Z3714&"-"&AC3714&"-"&AD3714&"-"&AG3714 -> 5.5-e-A-3-2.5 | Y3714: =F3714 -> 5.5 | Z3714: =G3714 -> e | AA3714: =_xlfn.IFNA(VLOOKUP(X3714,'duo-out'!A$2:Q$5000,5,FALSE),E3714+10*(H3714-1)+1+_xlfn.IFNA(VLOOKUP(D3714,states!A$2:C$10,3,FALSE),1)) -> 109 | AB3714: =IF(V3714="","",V3714) -> 31149.413 | AC3714: =_xlfn.IFNA(VLOOKUP(D3714,states!A$2:C$10,2,FALSE),"XX") -> A | AD3714: =E3714 -> 3 | AE3714: =_xlfn.IFNA(VLOOKUP(D3714,states!A$2:D$10,4,FALSE),0) -> 2 | AF3714: 0.5 | AG3714: =IF(AE3714=0,AF3714,IF(AE3714=1,IF(F3714=0.5,0.5,IF(H3714=1,0.5,1.5)),IF(F3714=0.5,0.5,IF(H3714=1,2.5,1.5)))) -> 2.5 | AH3714: =IF(AC3714="XX",0,1/C3714^(1/5)*IF(E3714=0,100,1)/(E3714+1)^(1/4)) -> 2.0402858
A3715: 3826 | B3715: 22788.718 | C3715: 0.02684 | D3715: A2Delta | E3715: 3 | F3715: 5.5 | G3715: e | H3715: 2 | I3715: X2Pi | J3715: 3 | K3715: 6.5 | L3715: e | M3715: 2 | N3715: 95Zachwiej.694 | O3715: 1 | P3715: =D3715&"-"&F3715&"-"&G3715&"-"&E3715&"-"&H3715 -> A2Delta-5.5-e-3-2 | Q3715: =I3715&"-"&K3715&"-"&L3715&"-"&J3715&"-"&M3715 -> X2Pi-6.5-e-3-2 | R3715: =B3715+S3715 -> 31296.871 | S3715: =_xlfn.IFNA(VLOOKUP(Q3715,'MARVEL-X'!A$2:I$1400,7,FALSE),VLOOKUP(Q3715,MARVEL!A$2:J$1522,10,FALSE)) -> 8508.1533 | T3715: =IF(P3715=P3714,R3715+T3714,R3715) -> 31296.871 | U3715: =IF(P3715=P3714,1+U3714,1) -> 1 | V3715: =IF(P3715=P3716,"",T3715/U3715) | W3715: =IF(V3715="","",IF(ABS(V3715-R3715)>W$1,ABS(V3715-R3715),"")) | X3715: =Y3715&"-"&Z3715&"-"&AC3715&"-"&AD3715&"-"&AG3715 -> 5.5-e-A-3-1.5 | Y3715: =F3715 -> 5.5 | Z3715: =G3715 -> e | AA3715: =_xlfn.IFNA(VLOOKUP(X3715,'duo-out'!A$2:Q$5000,5,FALSE),E3715+10*(H3715-1)+1+_xlfn.IFNA(VLOOKUP(D3715,states!A$2:C$10,3,FALSE),1)) -> 110 | AB3715: =IF(V3715="","",V3715) | AC3715: =_xlfn.IFNA(VLOOKUP(D3715,states!A$2:C$10,2,FALSE),"XX") -> A | AD3715: =E3715 -> 3 | AE3715: =_xlfn.IFNA(VLOOKUP(D3715,states!A$2:D$10,4,FALSE),0) -> 2 | AF3715: 0.5 | AG3715: =IF(AE3715=0,AF3715,IF(AE3715=1,IF(F3715=0.5,0.5,IF(H3715=1,0.5,1.5)),IF(F3715=0.5,0.5,IF(H3715=1,2.5,1.5)))) -> 1.5 | AH3715: =IF(AC3715="XX",0,1/C3715^(1/5)*IF(E3715=0,100,1)/(E3715+1)^(1/4)) -> 1.4579026
A3716: 3808 | B3716: 22961.853 | C3716: 0.005 | D3716: A2Delta | E3716: 3 | F3716: 5.5 | G3716: e | H3716: 2 | I3716: X2Pi | J3716: 3 | K3716: 5.5 | L3716: f | M3716: 2 | N3716: 95Zachwiej.676 | O3716: 1 | P3716: =D3716&"-"&F3716&"-"&G3716&"-"&E3716&"-"&H3716 -> A2Delta-5.5-e-3-2 | Q3716: =I3716&"-"&K3716&"-"&L3716&"-"&J3716&"-"&M3716 -> X2Pi-5.5-f-3-2 | R3716: =B3716+S3716 -> 31296.897 | S3716: =_xlfn.IFNA(VLOOKUP(Q3716,'MARVEL-X'!A$2:I$1400,7,FALSE),VLOOKUP(Q3716,MARVEL!A$2:J$1522,10,FALSE)) -> 8335.0443 | T3716: =IF(P3716=P3715,R3716+T3715,R3716) -> 62593.769 | U3716: =IF(P3716=P3715,1+U3715,1) -> 2 | V3716: =IF(P3716=P3717,"",T3716/U3716) | W3716: =IF(V3716="","",IF(ABS(V3716-R3716)>W$1,ABS(V3716-R3716),"")) | X3716: =Y3716&"-"&Z3716&"-"&AC3716&"-"&AD3716&"-"&AG3716 -> 5.5-e-A-3-1.5 | Y3716: =F3716 -> 5.5 | Z3716: =G3716 -> e | AA3716: =_xlfn.IFNA(VLOOKUP(X3716,'duo-out'!A$2:Q$5000,5,FALSE),E3716+10*(H3716-1)+1+_xlfn.IFNA(VLOOKUP(D3716,states!A$2:C$10,3,FALSE),1)) -> 110 | AB3716: =IF(V3716="","",V3716) | AC3716: =_xlfn.IFNA(VLOOKUP(D3716,states!A$2:C$10,2,FALSE),"XX") -> A | AD3716: =E3716 -> 3 | AE3716: =_xlfn.IFNA(VLOOKUP(D3716,states!A$2:D$10,4,FALSE),0) -> 2 | AF3716: 0.5 | AG3716: =IF(AE3716=0,AF3716,IF(AE3716=1,IF(F3716=0.5,0.5,IF(H3716=1,0.5,1.5)),IF(F3716=0.5,0.5,IF(H3716=1,2.5,1.5)))) -> 1.5 | AH3716: =IF(AC3716="XX",0,1/C3716^(1/5)*IF(E3716=0,100,1)/(E3716+1)^(1/4)) -> 2.0402858
A3717: 3801 | B3717: 23113.517 | C3717: 0.005 | D3717: A2Delta | E3717: 3 | F3717: 5.5 | G3717: e | H3717: 2 | I3717: X2Pi | J3717: 3 | K3717: 4.5 | L3717: e | M3717: 2 | N3717: 95Zachwiej.669 | O3717: 1 | P3717: =D3717&"-"&F3717&"-"&G3717&"-"&E3717&"-"&H3717 -> A2Delta-5.5-e-3-2 | Q3717: =I3717&"-"&K3717&"-"&L3717&"-"&J3717&"-"&M3717 -> X2Pi-4.5-e-3-2 | R3717: =B3717+S3717 -> 31296.896 | S3717: =_xlfn.IFNA(VLOOKUP(Q3717,'MARVEL-X'!A$2:I$1400,7,FALSE),VLOOKUP(Q3717,MARVEL!A$2:J$1522,10,FALSE)) -> 8183.3788 | T3717: =IF(P3717=P3716,R3717+T3716,R3717) -> 93890.665 | U3717: =IF(P3717=P3716,1+U3716,1) -> 3 | V3717: =IF(P3717=P3718,"",T3717/U3717) -> 31296.888 | W3717: =IF(V3717="","",IF(ABS(V3717-R3717)>W$1,ABS(V3717-R3717),"")) | X3717: =Y3717&"-"&Z3717&"-"&AC3717&"-"&AD3717&"-"&AG3717 -> 5.5-e-A-3-1.5 | Y3717: =F3717 -> 5.5 | Z3717: =G3717 -> e | AA3717: =_xlfn.IFNA(VLOOKUP(X3717,'duo-out'!A$2:Q$5000,5,FALSE),E3717+10*(H3717-1)+1+_xlfn.IFNA(VLOOKUP(D3717,states!A$2:C$10,3,FALSE),1)) -> 110 | AB3717: =IF(V3717="","",V3717) -> 31296.888 | AC3717: =_xlfn.IFNA(VLOOKUP(D3717,states!A$2:C$10,2,FALSE),"XX") -> A | AD3717: =E3717 -> 3 | AE3717: =_xlfn.IFNA(VLOOKUP(D3717,states!A$2:D$10,4,FALSE),0) -> 2 | AF3717: 0.5 | AG3717: =IF(AE3717=0,AF3717,IF(AE3717=1,IF(F3717=0.5,0.5,IF(H3717=1,0.5,1.5)),IF(F3717=0.5,0.5,IF(H3717=1,2.5,1.5)))) -> 1.5 | AH3717: =IF(AC3717="XX",0,1/C3717^(1/5)*IF(E3717=0,100,1)/(E3717+1)^(1/4)) -> 2.0402858
A3718: 6053 | B3718: 22684.18 | C3718: 0.5 | D3718: A2Delta | E3718: 4 | F3718: 5.5 | G3718: e | H3718: 1 | I3718: X2Pi | J3718: 4 | K3718: 5.5 | L3718: f | M3718: 1 | N3718: 14MaPlVaCo.338 | O3718: 1 | P3718: =D3718&"-"&F3718&"-"&G3718&"-"&E3718&"-"&H3718 -> A2Delta-5.5-e-4-1 | Q3718: =I3718&"-"&K3718&"-"&L3718&"-"&J3718&"-"&M3718 -> X2Pi-5.5-f-4-1 | R3718: =B3718+S3718 -> 33212.942 | S3718: =_xlfn.IFNA(VLOOKUP(Q3718,'MARVEL-X'!A$2:I$1400,7,FALSE),VLOOKUP(Q3718,MARVEL!A$2:J$1522,10,FALSE)) -> 10528.762 | T3718: =IF(P3718=P3717,R3718+T3717,R3718) -> 33212.942 | U3718: =IF(P3718=P3717,1+U3717,1) -> 1 | V3718: =IF(P3718=P3719,"",T3718/U3718) -> 33212.942 | W3718: =IF(V3718="","",IF(ABS(V3718-R3718)>W$1,ABS(V3718-R3718),"")) | X3718: =Y3718&"-"&Z3718&"-"&AC3718&"-"&AD3718&"-"&AG3718 -> 5.5-e-A-4-2.5 | Y3718: =F3718 -> 5.5 | Z3718: =G3718 -> e | AA3718: =_xlfn.IFNA(VLOOKUP(X3718,'duo-out'!A$2:Q$5000,5,FALSE),E3718+10*(H3718-1)+1+_xlfn.IFNA(VLOOKUP(D3718,states!A$2:C$10,3,FALSE),1)) -> 120 | AB3718: =IF(V3718="","",V3718) -> 33212.942 | AC3718: =_xlfn.IFNA(VLOOKUP(D3718,states!A$2:C$10,2,FALSE),"XX") -> A | AD3718: =E3718 -> 4 | AE3718: =_xlfn.IFNA(VLOOKUP(D3718,states!A$2:D$10,4,FALSE),0) -> 2 | AF3718: 0.5 | AG3718: =IF(AE3718=0,AF3718,IF(AE3718=1,IF(F3718=0.5,0.5,IF(H3718=1,0.5,1.5)),IF(F3718=0.5,0.5,IF(H3718=1,2.5,1.5)))) -> 2.5 | AH3718: =IF(AC3718="XX",0,1/C3718^(1/5)*IF(E3718=0,100,1)/(E3718+1)^(1/4)) -> 0.76818089
A3719: 6120 | B3719: 22509.21 | C3719: 0.5 | D3719: A2Delta | E3719: 4 | F3719: 5.5 | G3719: e | H3719: 2 | I3719: X2Pi | J3719: 4 | K3719: 6.5 | L3719: e | M3719: 2 | N3719: 14MaPlVaCo.420 | O3719: 1 | P3719: =D3719&"-"&F3719&"-"&G3719&"-"&E3719&"-"&H3719 -> A2Delta-5.5-e-4-2 | Q3719: =I3719&"-"&K3719&"-"&L3719&"-"&J3719&"-"&M3719 -> X2Pi-6.5-e-4-2 | R3719: =B3719+S3719 -> 33347.151 | S3719: =_xlfn.IFNA(VLOOKUP(Q3719,'MARVEL-X'!A$2:I$1400,7,FALSE),VLOOKUP(Q3719,MARVEL!A$2:J$1522,10,FALSE)) -> 10837.941 | T3719: =IF(P3719=P3718,R3719+T3718,R3719) -> 33347.151 | U3719: =IF(P3719=P3718,1+U3718,1) -> 1 | V3719: =IF(P3719=P3720,"",T3719/U3719) -> 33347.151 | W3719: =IF(V3719="","",IF(ABS(V3719-R3719)>W$1,ABS(V3719-R3719),"")) | X3719: =Y3719&"-"&Z3719&"-"&AC3719&"-"&AD3719&"-"&AG3719 -> 5.5-e-A-4-1.5 | Y3719: =F3719 -> 5.5 | Z3719: =G3719 -> e | AA3719: =_xlfn.IFNA(VLOOKUP(X3719,'duo-out'!A$2:Q$5000,5,FALSE),E3719+10*(H3719-1)+1+_xlfn.IFNA(VLOOKUP(D3719,states!A$2:C$10,3,FALSE),1)) -> 124 | AB3719: =IF(V3719="","",V3719) -> 33347.151 | AC3719: =_xlfn.IFNA(VLOOKUP(D3719,states!A$2:C$10,2,FALSE),"XX") -> A | AD3719: =E3719 -> 4 | AE3719: =_xlfn.IFNA(VLOOKUP(D3719,states!A$2:D$10,4,FALSE),0) -> 2 | AF3719: 0.5 | AG3719: =IF(AE3719=0,AF3719,IF(AE3719=1,IF(F3719=0.5,0.5,IF(H3719=1,0.5,1.5)),IF(F3719=0.5,0.5,IF(H3719=1,2.5,1.5)))) -> 1.5 | AH3719: =IF(AC3719="XX",0,1/C3719^(1/5)*IF(E3719=0,100,1)/(E3719+1)^(1/4)) -> 0.76818089
A3720: 6134 | B3720: 22354.24 | C3720: 0.5 | D3720: A2Delta | E3720: 5 | F3720: 5.5 | G3720: e | H3720: 1 | I3720: X2Pi | J3720: 5 | K3720: 4.5 | L3720: e | M3720: 1 | N3720: 14MaPlVaCo.439 | O3720: 1 | P3720: =D3720&"-"&F3720&"-"&G3720&"-"&E3720&"-"&H3720 -> A2Delta-5.5-e-5-1 | Q3720: =I3720&"-"&K3720&"-"&L3720&"-"&J3720&"-"&M3720 -> X2Pi-4.5-e-5-1 | R3720: =B3720+S3720 -> #N/A | S3720: =_xlfn.IFNA(VLOOKUP(Q3720,'MARVEL-X'!A$2:I$1400,7,FALSE),VLOOKUP(Q3720,MARVEL!A$2:J$1522,10,FALSE)) -> #N/A | T3720: =IF(P3720=P3719,R3720+T3719,R3720) -> #N/A | U3720: =IF(P3720=P3719,1+U3719,1) -> 1 | V3720: =IF(P3720=P3721,"",T3720/U3720) -> #N/A | W3720: =IF(V3720="","",IF(ABS(V3720-R3720)>W$1,ABS(V3720-R3720),"")) -> #N/A | X3720: =Y3720&"-"&Z3720&"-"&AC3720&"-"&AD3720&"-"&AG3720 -> 5.5-e-A-5-2.5 | Y3720: =F3720 -> 5.5 | Z3720: =G3720 -> e | AA3720: =_xlfn.IFNA(VLOOKUP(X3720,'duo-out'!A$2:Q$5000,5,FALSE),E3720+10*(H3720-1)+1+_xlfn.IFNA(VLOOKUP(D3720,states!A$2:C$10,3,FALSE),1)) -> 256 | AB3720: =IF(V3720="","",V3720) -> #N/A | AC3720: =_xlfn.IFNA(VLOOKUP(D3720,states!A$2:C$10,2,FALSE),"XX") -> A | AD3720: =E3720 -> 5 | AE3720: =_xlfn.IFNA(VLOOKUP(D3720,states!A$2:D$10,4,FALSE),0) -> 2 | AF3720: 0.5 | AG3720: =IF(AE3720=0,AF3720,IF(AE3720=1,IF(F3720=0.5,0.5,IF(H3720=1,0.5,1.5)),IF(F3720=0.5,0.5,IF(H3720=1,2.5,1.5)))) -> 2.5 | AH3720: =IF(AC3720="XX",0,1/C3720^(1/5)*IF(E3720=0,100,1)/(E3720+1)^(1/4)) -> 0.73395289
A3721: 3898 | B3721: 20468.318 | C3721: 0.01693 | D3721: A2Delta | E3721: 0 | F3721: 5.5 | G3721: f | H3721: 1 | I3721: X2Pi | J3721: 1 | K3721: 4.5 | L3721: f | M3721: 2 | N3721: 95Zachwiej.767 | O3721: 1 | P3721: =D3721&"-"&F3721&"-"&G3721&"-"&E3721&"-"&H3721 -> A2Delta-5.5-f-0-1 | Q3721: =I3721&"-"&K3721&"-"&L3721&"-"&J3721&"-"&M3721 -> X2Pi-4.5-f-1-2 | R3721: =B3721+S3721 -> 23594.865 | S3721: =_xlfn.IFNA(VLOOKUP(Q3721,'MARVEL-X'!A$2:I$1400,7,FALSE),VLOOKUP(Q3721,MARVEL!A$2:J$1522,10,FALSE)) -> 3126.5469 | T3721: =IF(P3721=P3720,R3721+T3720,R3721) -> 23594.865 | U3721: =IF(P3721=P3720,1+U3720,1) -> 1 | V3721: =IF(P3721=P3722,"",T3721/U3721) | W3721: =IF(V3721="","",IF(ABS(V3721-R3721)>W$1,ABS(V3721-R3721),"")) | X3721: =Y3721&"-"&Z3721&"-"&AC3721&"-"&AD3721&"-"&AG3721 -> 5.5-f-A-0-2.5 | Y3721: =F3721 -> 5.5 | Z3721: =G3721 -> f | AA3721: =_xlfn.IFNA(VLOOKUP(X3721,'duo-out'!A$2:Q$5000,5,FALSE),E3721+10*(H3721-1)+1+_xlfn.IFNA(VLOOKUP(D3721,states!A$2:C$10,3,FALSE),1)) -> 51 | AB3721: =IF(V3721="","",V3721) | AC3721: =_xlfn.IFNA(VLOOKUP(D3721,states!A$2:C$10,2,FALSE),"XX") -> A | AD3721: =E3721 -> 0 | AE3721: =_xlfn.IFNA(VLOOKUP(D3721,states!A$2:D$10,4,FALSE),0) -> 2 | AF3721: 0.5 | AG3721: =IF(AE3721=0,AF3721,IF(AE3721=1,IF(F3721=0.5,0.5,IF(H3721=1,0.5,1.5)),IF(F3721=0.5,0.5,IF(H3721=1,2.5,1.5)))) -> 2.5 | AH3721: =IF(AC3721="XX",0,1/C3721^(1/5)*IF(E3721=0,100,1)/(E3721+1)^(1/4)) -> 226.08336
A3722: 3884 | B3722: 20304.714 | C3722: 0.005 | D3722: A2Delta | E3722: 0 | F3722: 5.5 | G3722: f | H3722: 1 | I3722: X2Pi | J3722: 1 | K3722: 6.5 | L3722: f | M3722: 1 | N3722: 95Zachwiej.753 | O3722: 1 | P3722: =D3722&"-"&F3722&"-"&G3722&"-"&E3722&"-"&H3722 -> A2Delta-5.5-f-0-1 | Q3722: =I3722&"-"&K3722&"-"&L3722&"-"&J3722&"-"&M3722 -> X2Pi-6.5-f-1-1 | R3722: =B3722+S3722 -> 23594.874 | S3722: =_xlfn.IFNA(VLOOKUP(Q3722,'MARVEL-X'!A$2:I$1400,7,FALSE),VLOOKUP(Q3722,MARVEL!A$2:J$1522,10,FALSE)) -> 3290.1603 | T3722: =IF(P3722=P3721,R3722+T3721,R3722) -> 47189.739 | U3722: =IF(P3722=P3721,1+U3721,1) -> 2 | V3722: =IF(P3722=P3723,"",T3722/U3722) | W3722: =IF(V3722="","",IF(ABS(V3722-R3722)>W$1,ABS(V3722-R3722),"")) | X3722: =Y3722&"-"&Z3722&"-"&AC3722&"-"&AD3722&"-"&AG3722 -> 5.5-f-A-0-2.5 | Y3722: =F3722 -> 5.5 | Z3722: =G3722 -> f | AA3722: =_xlfn.IFNA(VLOOKUP(X3722,'duo-out'!A$2:Q$5000,5,FALSE),E3722+10*(H3722-1)+1+_xlfn.IFNA(VLOOKUP(D3722,states!A$2:C$10,3,FALSE),1)) -> 51 | AB3722: =IF(V3722="","",V3722) | AC3722: =_xlfn.IFNA(VLOOKUP(D3722,states!A$2:C$10,2,FALSE),"XX") -> A | AD3722: =E3722 -> 0 | AE3722: =_xlfn.IFNA(VLOOKUP(D3722,states!A$2:D$10,4,FALSE),0) -> 2 | AF3722: 0.5 | AG3722: =IF(AE3722=0,AF3722,IF(AE3722=1,IF(F3722=0.5,0.5,IF(H3722=1,0.5,1.5)),IF(F3722=0.5,0.5,IF(H3722=1,2.5,1.5)))) -> 2.5 | AH3722: =IF(AC3722="XX",0,1/C3722^(1/5)*IF(E3722=0,100,1)/(E3722+1)^(1/4)) -> 288.53998
A3723: 3849 | B3723: 20466.04 | C3723: 0.005 | D3723: A2Delta | E3723: 0 | F3723: 5.5 | G3723: f | H3723: 1 | I3723: X2Pi | J3723: 1 | K3723: 5.5 | L3723: e | M3723: 1 | N3723: 95Zachwiej.718 | O3723: 1 | P3723: =D3723&"-"&F3723&"-"&G3723&"-"&E3723&"-"&H3723 -> A2Delta-5.5-f-0-1 | Q3723: =I3723&"-"&K3723&"-"&L3723&"-"&J3723&"-"&M3723 -> X2Pi-5.5-e-1-1 | R3723: =B3723+S3723 -> 23594.875 | S3723: =_xlfn.IFNA(VLOOKUP(Q3723,'MARVEL-X'!A$2:I$1400,7,FALSE),VLOOKUP(Q3723,MARVEL!A$2:J$1522,10,FALSE)) -> 3128.8352 | T3723: =IF(P3723=P3722,R3723+T3722,R3723) -> 70784.614 | U3723: =IF(P3723=P3722,1+U3722,1) -> 3 | V3723: =IF(P3723=P3724,"",T3723/U3723) | W3723: =IF(V3723="","",IF(ABS(V3723-R3723)>W$1,ABS(V3723-R3723),"")) | X3723: =Y3723&"-"&Z3723&"-"&AC3723&"-"&AD3723&"-"&AG3723 -> 5.5-f-A-0-2.5 | Y3723: =F3723 -> 5.5 | Z3723: =G3723 -> f | AA3723: =_xlfn.IFNA(VLOOKUP(X3723,'duo-out'!A$2:Q$5000,5,FALSE),E3723+10*(H3723-1)+1+_xlfn.IFNA(VLOOKUP(D3723,states!A$2:C$10,3,FALSE),1)) -> 51 | AB3723: =IF(V3723="","",V3723) | AC3723: =_xlfn.IFNA(VLOOKUP(D3723,states!A$2:C$10,2,FALSE),"XX") -> A | AD3723: =E3723 -> 0 | AE3723: =_xlfn.IFNA(VLOOKUP(D3723,states!A$2:D$10,4,FALSE),0) -> 2 | AF3723: 0.5 | AG3723: =IF(AE3723=0,AF3723,IF(AE3723=1,IF(F3723=0.5,0.5,IF(H3723=1,0.5,1.5)),IF(F3723=0.5,0.5,IF(H3723=1,2.5,1.5)))) -> 2.5 | AH3723: =IF(AC3723="XX",0,1/C3723^(1/5)*IF(E3723=0,100,1)/(E3723+1)^(1/4)) -> 288.53998
